Workbook

Sheet Plantilla SIG
C1: PLANTILLA SIG COMPROMISOS INSTITUCIONALES | G1: DIVISIÓN PLANIFICACION Y DESARROLLO
G2: DEPARTAMENTO COMPROMISOS INSTITUCIONALES
G3: SUBDEPARTAMENTO GESTION DE INDICADORES INSTITUCIONALES
G5: Fecha: julio 2025
B6: Elaborado por: Analista de Gestión | C6: Revisado por: Jefa Subdepartamento Gestión de Indicadores Institucionales | G6: Aprobado por: Jefa Departamento Compromisos Institucionales
B8: Convenio de Desempeño Alta Dirección Pública
B9: Director Regional - Región de Coquimbo, Sr. Juan Paulo Garrido Piccioli
B10: Primer Período, tercer año julio 2025 - junio 2026
A11: NUMERO | B11: INDICADOR | C11: FORMULA | D11: PONDERACIÓN | E11: Meta a agosto 2026 | F11: Operandos | G11: Operandos Estimados Meta | H11: 45839 | I11: 45870 | J11: Acum. | K11: 45901 | L11: Acum. | M11: 45931 | N11: Acum. | O11: 45962 | P11: Acum. | Q11: 45992 | R11: Acum. | S11: 46023 | T11: Acum. | U11: 46054 | V11: Acum. | W11: 38777 | X11: Acum. | Y11: 46113 | Z11: Acum. | AA11: 46143 | AB11: Acum. | AC11: 46174 | AD11: Cumplimiento Efectivo a la fecha | AE11: % Cumplimiento de Meta
A13: ADP_DR04_04 | B13: 4.Porcentaje de líneas de acción implementadas del Plan de Calidad de Servicios en la región en el año t | C13: (Numero de lineas de accion implentadas del Plan de Calidad de Servicio en la región en el año t / Total de líneas de acción definidas en el Plan de calidad de Servicios en año t) *100) | D13: 0.2 | E13: 1 | F13: Numero de lineas de accion implentadas del Plan de Calidad de Servicio en la región en el año t | G13: Valor indicador= | H13: Valor indicador= | I13: Valor indicador= | J13: Valor indicador= | K13: Valor indicador= | L13: Valor indicador= | M13: Valor indicador= | N13: Valor indicador= | O13: Valor indicador= | P13: Valor indicador= | Q13: Valor indicador= | R13: Valor indicador= | S13: Valor indicador= | T13: Valor indicador= | U13: Valor indicador= | V13: Valor indicador= | W13: Valor indicador= | X13: Valor indicador= | Y13: Valor indicador= | Z13: Valor indicador= | AA13: Valor indicador= | AB13: Valor indicador= | AC13: Valor indicador= | AD13: Valor indicador=
G14: =+E13 -> 1 | H14: =IF(H16<>0,+H16/H18,0%) -> 0 | I14: =IF(I16<>0,+I16/I18,0%) -> 0 | J14: =IF(J16<>0,ROUND(+J16/J18,4),0%) -> 0 | K14: =IF(K16<>0,+K16/K18,0%) -> 0 | L14: =IF(L16<>0,ROUND(+L16/L18,4),0%) -> 0 | M14: =IF(M16<>0,+M16/M18,0%) -> 0 | N14: =IF(N16<>0,ROUND(+N16/N18,4),0%) -> 0 | O14: =IF(O16<>0,+O16/O18,0%) -> 0 | P14: =IF(P16<>0,ROUND(+P16/P18,4),0%) -> 0 | Q14: =IF(Q16<>0,+Q16/Q18,0%) -> 0.66666667 | R14: =IF(R16<>0,ROUND(+R16/R18,4),0%) -> 0.6667 | S14: =IF(S16<>0,ROUND(+S16/S18,4),0%) -> 0 | T14: =IF(T16<>0,ROUND(+T16/T18,4),0%) -> 0.6667 | U14: =IF(U16<>0,ROUND(+U16/U18,4),0%) -> 0 | V14: =IF(V16<>0,ROUND(+V16/V18,4),0%) -> 0.6667 | W14: =IF(W16<>0,ROUND(+W16/W18,4),0%) -> 0 | X14: =IF(X16<>0,ROUND(+X16/X18,4),0%) -> 0.6667 | Y14: =IF(Y16<>0,ROUND(+Y16/Y18,4),0%) -> 0 | ... AC14: =IF(AC16<>0,ROUND(+AC16/AC18,4),0%) -> 0 | AD14: =IF(AD16<>0,+AD16/AD18,0%) -> 0.66666667
G15: Operando 1= | H15: Operando 1= | I15: Operando 1= | J15: Operando 1= | K15: Operando 1= | L15: Operando 1= | M15: Operando 1= | N15: Operando 1= | O15: Operando 1= | P15: Operando 1= | Q15: Operando 1= | R15: Operando 1= | S15: Operando 1= | T15: Operando 1= | U15: Operando 1= | V15: Operando 1= | W15: Operando 1= | X15: Operando 1= | Y15: Operando 1= | Z15: Operando 1= | AA15: Operando 1= | AB15: Operando 1= | AC15: Operando 1= | AD15: Operando 1=
F16: Total de líneas de acción definidas en el Plan de calidad de Servicios en año t | G16: 3 | H16: 0 | I16: 0 | J16: =+H16+I16 -> 0 | K16: 0 | L16: =+J16+K16 -> 0 | M16: 0 | N16: =+L16+M16 -> 0 | O16: 0 | P16: =+N16+O16 -> 0 | Q16: 2 | R16: =+P16+Q16 -> 2 | S16: 0 | T16: =+R16+S16 -> 2 | U16: 0 | V16: =+T16+U16 -> 2 | W16: 0 | X16: =+V16+W16 -> 2 | Y16: 0 | Z16: =+X16+Y16 -> 2 | AA16: 0 | AB16: =+Z16+AA16 -> 2 | AC16: 0 | AD16: =+AB16+AC16 -> 2 | AE16: =AD14/E13 -> 0.66666667
G17: Operando 2= | H17: Operando 2= | I17: Operando 2= | J17: Operando 2= | K17: Operando 2= | L17: Operando 2= | M17: Operando 2= | N17: Operando 2= | O17: Operando 2= | P17: Operando 2= | Q17: Operando 2= | R17: Operando 2= | S17: Operando 2= | T17: Operando 2= | U17: Operando 2= | V17: Operando 2= | W17: Operando 2= | X17: Operando 2= | Y17: Operando 2= | Z17: Operando 2= | AA17: Operando 2= | AB17: Operando 2= | AC17: Operando 2= | AD17: Operando 2=
G18: 3 | H18: 3 | I18: 3 | J18: =+I18 -> 3 | K18: 3 | L18: =+K18 -> 3 | M18: 3 | N18: =+M18 -> 3 | O18: 3 | P18: =+O18 -> 3 | Q18: 3 | R18: =+Q18 -> 3 | S18: 3 | T18: =+S18 -> 3 | U18: 3 | V18: =+U18 -> 3 | W18: 3 | X18: =+W18 -> 3 | Y18: 3 | Z18: =+Y18 -> 3 | AA18: 3 | AB18: =+AA18 -> 3 | AC18: 3 | AD18: =+AC18 -> 3
A19: ADP_DR04_05 | B19: 5. Porcentaje de actividades cumplidas del Plan de difusión en materias de Estado Verde en el año t | C19: (Número de actividades cumplidas del Plan de difusión en materias de Estado Verde desarrolladas en la región en el año t / Número total de actividades cumplidas del Plan de difusión en materias de Estado Verde programados en la región en el año t)* 100 | D19: 0.1 | E19: 1 | F19: (Número de actividades cumplidas del Plan de difusión en materias de Estado Verde desarrolladas en la región en el año t | G19: Valor indicador= | H19: Valor indicador= | I19: Valor indicador= | J19: Valor indicador= | K19: Valor indicador= | L19: Valor indicador= | M19: Valor indicador= | N19: Valor indicador= | O19: Valor indicador= | P19: Valor indicador= | Q19: Valor indicador= | R19: Valor indicador= | S19: Valor indicador= | T19: Valor indicador= | U19: Valor indicador= | V19: Valor indicador= | W19: Valor indicador= | X19: Valor indicador= | Y19: Valor indicador= | Z19: Valor indicador= | AA19: Valor indicador= | AB19: Valor indicador= | AC19: Valor indicador= | AD19: Valor indicador=
G20: =IF(G22<>0,+G22/G24,0%) -> 1 | H20: =IF(H22<>0,+H22/H24,0%) -> 0 | I20: =IF(I22<>0,+I22/I24,0%) -> 0 | J20: =IF(J22<>0,+J22/J24,0%) -> 0 | K20: =IF(K22<>0,+K22/K24,0%) -> 0 | L20: =IF(L22<>0,+L22/L24,0%) -> 0 | M20: =IF(M22<>0,+M22/M24,0%) -> 0 | N20: =IF(N22<>0,+N22/N24,0%) -> 0 | ... AD20: =IF(AD22<>0,+AD22/AD24,0%) -> 0
G21: Operando 1= | H21: Operando 1= | J21: Operando 1= | K21: Operando 1= | L21: Operando 1= | M21: Operando 1= | N21: Operando 1= | O21: Operando 1= | P21: Operando 1= | Q21: Operando 1= | R21: Operando 1= | S21: Operando 1= | T21: Operando 1= | U21: Operando 1= | V21: Operando 1= | W21: Operando 1= | X21: Operando 1= | Y21: Operando 1= | Z21: Operando 1= | AA21: Operando 1= | AB21: Operando 1= | AC21: Operando 1= | AD21: Operando 1=
F22: Número total de actividades cumplidas del Plan de difusión en materias de Estado Verde programados en la región en el año t)* 100 | G22: 2 | H22: 0 | I22: 0 | J22: =+H22+I22 -> 0 | K22: 0 | L22: =+J22+K22 -> 0 | M22: 0 | N22: =+L22+M22 -> 0 | O22: 0 | P22: =+N22+O22 -> 0 | Q22: 0 | R22: =+P22+Q22 -> 0 | S22: 0 | T22: =+R22+S22 -> 0 | U22: 0 | V22: =+T22+U22 -> 0 | W22: 0 | X22: =+V22+W22 -> 0 | Y22: 0 | Z22: =+X22+Y22 -> 0 | AA22: 0 | AB22: =+Z22+AA22 -> 0 | AC22: 0 | AD22: =+AB22+AC22 -> 0 | AE22: =AD20/E19 -> 0
G23: Operando 2= | H23: Operando 2= | I23: Operando 2= | J23: Operando 2= | K23: Operando 2= | L23: Operando 2= | M23: Operando 2= | N23: Operando 2= | O23: Operando 2= | P23: Operando 2= | Q23: Operando 2= | R23: Operando 2= | S23: Operando 2= | T23: Operando 2= | U23: Operando 2= | V23: Operando 2= | W23: Operando 2= | X23: Operando 2= | Y23: Operando 2= | Z23: Operando 2= | AA23: Operando 2= | AB23: Operando 2= | AC23: Operando 2= | AD23: Operando 2=
G24: 2 | H24: 2 | I24: 2 | J24: =I24 -> 2 | K24: 2 | L24: =K24 -> 2 | M24: 2 | N24: =M24 -> 2 | O24: 2 | P24: =O24 -> 2 | Q24: 2 | R24: =Q24 -> 2 | S24: 2 | T24: =S24 -> 2 | U24: 2 | V24: =U24 -> 2 | W24: 2 | X24: =W24 -> 2 | Y24: 2 | Z24: =Y24 -> 2 | AA24: 2 | AB24: =AA24 -> 2 | AC24: 2 | AD24: =AC24 -> 2
A25: ADP_DR04_07 | B25: 7. Porcentaje de funcionarios/as capacitados en la región en temáticas de Integridad en el | C25: (Sumatoria de funcionarios/as capacitados en la región en temáticas de Integridad en el año t / Dotación de funcionarios/as de la Región en el año t)*100 | D25: 0.1 | E25: 0.2 | F25: Sumatoria de funcionarios/as capacitados en la región en temáticas de Integridad en el año t | G25: Valor indicador= | H25: Valor indicador= | I25: Valor indicador= | J25: Valor indicador= | K25: Valor indicador= | L25: Valor indicador= | M25: Valor indicador= | N25: Valor indicador= | O25: Valor indicador= | P25: Valor indicador= | Q25: Valor indicador= | R25: Valor indicador= | S25: Valor indicador= | T25: Valor indicador= | U25: Valor indicador= | V25: Valor indicador= | W25: Valor indicador= | X25: Valor indicador= | Y25: Valor indicador= | Z25: Valor indicador= | AA25: Valor indicador= | AB25: Valor indicador= | AC25: Valor indicador= | AD25: Valor indicador=
G26: =IF(G28<>0,+G28/G30,0%) -> 0.2 | H26: =IF(H28<>0,+H28/H30,0%) -> 0 | I26: =IF(I28<>0,+I28/I30,0%) -> 0 | J26: =IF(J28<>0,ROUND(+J28/J30,4),0%) -> 0 | K26: =IF(K28<>0,+K28/K30,0%) -> 0 | L26: =IF(L28<>0,ROUND(+L28/L30,4),0%) -> 0 | M26: =IF(M28<>0,+M28/M30,0%) -> 0 | N26: =IF(N28<>0,ROUND(+N28/N30,4),0%) -> 0 | O26: =IF(O28<>0,+O28/O30,0%) -> 0 | P26: =IF(P28<>0,ROUND(+P28/P30,4),0%) -> 0 | Q26: =IF(Q28<>0,+Q28/Q30,0%) -> 0 | R26: =IF(R28<>0,ROUND(+R28/R30,4),0%) -> 0 | S26: =IF(S28<>0,+S28/S30,0%) -> 0 | T26: =IF(T28<>0,ROUND(+T28/T30,4),0%) -> 0 | U26: =IF(U28<>0,+U28/U30,0%) -> 0 | V26: =IF(V28<>0,ROUND(+V28/V30,4),0%) -> 0 | W26: =IF(W28<>0,+W28/W30,0%) -> 0 | X26: =IF(X28<>0,ROUND(+X28/X30,4),0%) -> 0 | Y26: =IF(Y28<>0,+Y28/Y30,0%) -> 0 | Z26: =IF(Z28<>0,ROUND(+Z28/Z30,4),0%) -> 0 | AA26: =IF(AA28<>0,+AA28/AA30,0%) -> 0 | AB26: =IF(AB28<>0,ROUND(+AB28/AB30,4),0%) -> 0 | AC26: =IF(AC28<>0,+AC28/AC30,0%) -> 0 | AD26: =IF(AD28<>0,ROUND(+AD28/AD30,4),0%) -> 0
G27: Operando 1= | H27: Operando 1= | I27: Operando 1= | J27: Operando 1= | K27: Operando 1= | L27: Operando 1= | M27: Operando 1= | N27: Operando 1= | O27: Operando 1= | P27: Operando 1= | Q27: Operando 1= | R27: Operando 1= | S27: Operando 1= | T27: Operando 1= | U27: Operando 1= | V27: Operando 1= | W27: Operando 1= | X27: Operando 1= | Y27: Operando 1= | Z27: Operando 1= | AA27: Operando 1= | AB27: Operando 1= | AC27: Operando 1= | AD27: Operando 1=
F28: Dotación de funcionarios/as de la Región en el año t)*100 | G28: 17.2 | H28: 0 | I28: 0 | J28: =+H28+I28 -> 0 | K28: 0 | L28: =+J28+K28 -> 0 | M28: 0 | N28: =+L28+M28 -> 0 | O28: 0 | P28: =+N28+O28 -> 0 | Q28: 0 | R28: =+P28+Q28 -> 0 | S28: 0 | T28: =+R28+S28 -> 0 | U28: 0 | V28: =+T28+U28 -> 0 | W28: 0 | X28: =+V28+W28 -> 0 | Y28: 0 | Z28: =+X28+Y28 -> 0 | AA28: 0 | AB28: =+Z28+AA28 -> 0 | AC28: 0 | AD28: =+AB28+AC28 -> 0 | AE28: =AD26/E25 -> 0
H29: Operando 2= | I29: Operando 2= | J29: Operando 2= | K29: Operando 2= | L29: Operando 2= | M29: Operando 2= | N29: Operando 2= | O29: Operando 2= | P29: Operando 2= | Q29: Operando 2= | R29: Operando 2= | S29: Operando 2= | T29: Operando 2= | U29: Operando 2= | V29: Operando 2= | W29: Operando 2= | X29: Operando 2= | Y29: Operando 2= | Z29: Operando 2= | AA29: Operando 2= | AB29: Operando 2= | AC29: Operando 2= | AD29: Operando 2=
G30: 86 | H30: 86 | I30: 86 | J30: 86 | K30: 86 | L30: 86 | M30: 86 | N30: 86 | O30: 86 | P30: 86 | Q30: 86 | R30: 86 | S30: 86 | T30: 86 | U30: 86 | V30: 86 | W30: 86 | X30: 86 | Y30: 86 | Z30: 86 | AA30: 86 | AB30: 86 | AC30: 86 | AD30: 86
A31: ADP_DR04_08 | B31: 8. Porcentaje de actividades cumplidas del Plan para generar iniciativas de innovación, en el año t | C31: (Sumatoria de actividades cumplidas del Plan para generar iniciativas de innovación, en el año t / Número total de actividades definidas en el Plan en el periodo) *100 | D31: 0.1 | E31: 1 | F31: Sumatoria de actividades cumplidas del Plan para generar iniciativas de innovación, en el año t | G31: Valor indicador= | H31: Valor indicador= | I31: Valor indicador= | J31: Valor indicador= | K31: Valor indicador= | L31: Valor indicador= | M31: Valor indicador= | N31: Valor indicador= | O31: Valor indicador= | P31: Valor indicador= | Q31: Valor indicador= | R31: Valor indicador= | S31: Valor indicador= | T31: Valor indicador= | U31: Valor indicador= | V31: Valor indicador= | W31: Valor indicador= | X31: Valor indicador= | Y31: Valor indicador= | Z31: Valor indicador= | AA31: Valor indicador= | AB31: Valor indicador= | AC31: Valor indicador= | AD31: Valor indicador=
G32: =IF(G34<>0,+G34/G36,0%) -> 1 | H32: =IF(H34<>0,+H34/H36,0%) -> 0 | I32: =IF(I34<>0,+I34/I36,0%) -> 0 | J32: =IF(J34<>0,+J34/J36,0%) -> 0 | K32: =IF(K34<>0,+K34/K36,0%) -> 0 | L32: =IF(L34<>0,+L34/L36,0%) -> 0 | M32: =IF(M34<>0,+M34/M36,0%) -> 0 | N32: =IF(N34<>0,+N34/N36,0%) -> 0 | ... AD32: =IF(AD34<>0,+AD34/AD36,0%) -> 0.4
G33: Operando 1= | H33: Operando 1= | J33: Operando 1= | K33: Operando 1= | L33: Operando 1= | M33: Operando 1= | N33: Operando 1= | O33: Operando 1= | P33: Operando 1= | Q33: Operando 1= | R33: Operando 1= | S33: Operando 1= | T33: Operando 1= | U33: Operando 1= | V33: Operando 1= | W33: Operando 1= | X33: Operando 1= | Y33: Operando 1= | Z33: Operando 1= | AA33: Operando 1= | AB33: Operando 1= | AC33: Operando 1= | AD33: Operando 1=
F34: Sumatoria total de actividades definidas en el Plan en el periodo | G34: 5 | H34: 0 | I34: 0 | J34: =+H34+I34 -> 0 | K34: 0 | L34: =+J34+K34 -> 0 | M34: 0 | N34: =+L34+M34 -> 0 | O34: 1 | P34: =+N34+O34 -> 1 | Q34: 1 | R34: =+P34+Q34 -> 2 | S34: 0 | T34: =+R34+S34 -> 2 | U34: 0 | V34: =+T34+U34 -> 2 | W34: 0 | X34: =+V34+W34 -> 2 | Y34: 0 | Z34: =+X34+Y34 -> 2 | AA34: 0 | AB34: =+Z34+AA34 -> 2 | AC34: 0 | AD34: =+AB34+AC34 -> 2 | AE34: =AD32/E31 -> 0.4
G35: Operando 2= | H35: Operando 2= | I35: Operando 2= | J35: Operando 2= | K35: Operando 2= | L35: Operando 2= | M35: Operando 2= | N35: Operando 2= | O35: Operando 2= | P35: Operando 2= | Q35: Operando 2= | R35: Operando 2= | S35: Operando 2= | T35: Operando 2= | U35: Operando 2= | V35: Operando 2= | W35: Operando 2= | X35: Operando 2= | Y35: Operando 2= | Z35: Operando 2= | AA35: Operando 2= | AB35: Operando 2= | AC35: Operando 2= | AD35: Operando 2=
G36: 5 | H36: 5 | I36: 5 | J36: =I36 -> 5 | K36: 5 | L36: =K36 -> 5 | M36: 5 | N36: =M36 -> 5 | O36: 5 | P36: =O36 -> 5 | Q36: 5 | R36: =Q36 -> 5 | S36: 5 | T36: =S36 -> 5 | U36: 5 | V36: =U36 -> 5 | W36: 5 | X36: =W36 -> 5 | Y36: 5 | Z36: =Y36 -> 5 | AA36: 5 | AB36: =AA36 -> 5 | AC36: 5 | AD36: =AC36 -> 5
A37: ADP_DR04_09 | B37: 9. Porcentaje de actividades cumplidas del Plan de Difusión de temáticas de Seguridad Social y otras en la comunidad en el año t | C37: (Sumatoria de actividades cumplidas del Plan de Difusión de temáticas de Seguridad Social y otras en la comunidad en el año t / N° total de actividades programadas del Plan en el año t) *100 | D37: 0.1 | E37: 1 | F37: (Sumatoria de actividades cumplidas del Plan de Difusión de temáticas de Seguridad Social y otras en la comunidad en el año t | G37: Valor indicador= | H37: Valor indicador= | I37: Valor indicador= | J37: Valor indicador= | K37: Valor indicador= | L37: Valor indicador= | M37: Valor indicador= | N37: Valor indicador= | O37: Valor indicador= | P37: Valor indicador= | Q37: Valor indicador= | R37: Valor indicador= | S37: Valor indicador= | T37: Valor indicador= | U37: Valor indicador= | V37: Valor indicador= | W37: Valor indicador= | X37: Valor indicador= | Y37: Valor indicador= | Z37: Valor indicador= | AA37: Valor indicador= | AB37: Valor indicador= | AC37: Valor indicador= | AD37: Valor indicador=
G38: =IF(G40<>0,+G40/G42,0%) -> 1 | H38: =IF(H40<>0,+H40/H42,0%) -> 0.1 | I38: =IF(I40<>0,+I40/I42,0%) -> 0.1 | J38: =IF(J40<>0,+J40/J42,0%) -> 0.2 | K38: =IF(K40<>0,+K40/K42,0%) -> 0.1 | L38: =IF(L40<>0,+L40/L42,0%) -> 0.3 | M38: =IF(M40<>0,+M40/M42,0%) -> 0 | N38: =IF(N40<>0,+N40/N42,0%) -> 0.3 | ... AD38: =IF(AD40<>0,+AD40/AD42,0%) -> 0.4
G39: Operando 1= | H39: Operando 1= | J39: Operando 1= | K39: Operando 1= | L39: Operando 1= | M39: Operando 1= | N39: Operando 1= | O39: Operando 1= | P39: Operando 1= | Q39: Operando 1= | R39: Operando 1= | S39: Operando 1= | T39: Operando 1= | U39: Operando 1= | V39: Operando 1= | W39: Operando 1= | X39: Operando 1= | Y39: Operando 1= | Z39: Operando 1= | AA39: Operando 1= | AB39: Operando 1= | AC39: Operando 1= | AD39: Operando 1=
F40: N° total de actividades programadas del Plan en el año t) *100 | G40: 10 | H40: 1 | I40: 1 | J40: =+H40+I40 -> 2 | K40: 1 | L40: =+J40+K40 -> 3 | M40: 0 | N40: =+L40+M40 -> 3 | O40: 0 | P40: =+N40+O40 -> 3 | Q40: 1 | R40: =+P40+Q40 -> 4 | S40: 0 | T40: =+R40+S40 -> 4 | U40: 0 | V40: =+T40+U40 -> 4 | W40: 0 | X40: =+V40+W40 -> 4 | Y40: 0 | Z40: =+X40+Y40 -> 4 | AA40: 0 | AB40: =+Z40+AA40 -> 4 | AC40: 0 | AD40: =+AB40+AC40 -> 4 | AE40: =AD38/E37 -> 0.4
G41: Operando 2= | H41: Operando 2= | I41: Operando 2= | J41: Operando 2= | K41: Operando 2= | L41: Operando 2= | M41: Operando 2= | N41: Operando 2= | O41: Operando 2= | P41: Operando 2= | Q41: Operando 2= | R41: Operando 2= | S41: Operando 2= | T41: Operando 2= | U41: Operando 2= | V41: Operando 2= | W41: Operando 2= | X41: Operando 2= | Y41: Operando 2= | Z41: Operando 2= | AA41: Operando 2= | AB41: Operando 2= | AC41: Operando 2= | AD41: Operando 2=
G42: 10 | H42: 10 | I42: 10 | J42: =I42 -> 10 | K42: 10 | L42: =K42 -> 10 | M42: 10 | N42: =M42 -> 10 | O42: 10 | P42: =O42 -> 10 | Q42: 10 | R42: =Q42 -> 10 | S42: 10 | T42: =S42 -> 10 | U42: 10 | V42: =U42 -> 10 | W42: 10 | X42: =W42 -> 10 | Y42: 10 | Z42: =Y42 -> 10 | AA42: 10 | AB42: =AA42 -> 10 | AC42: 10 | AD42: =AC42 -> 10
A43: ADP_DR04_10 | B43: 10. Porcentaje de actividades cumplidas del plan de acción para la Satisfacción Laboral en el año t | C43: (Sumatoria de actividades cumplidas del plan de acción para la Satisfacción Laboral en al año t / N° total de actividades programadas del plan de acción para la Satisfacción Laboral en el año t)*100 | D43: 0.2 | E43: 1 | F43: (Sumatoria de actividades cumplidas del plan de acción para la Satisfacción Laboral en al año t | G43: Valor indicador= | H43: Valor indicador= | I43: Valor indicador= | J43: Valor indicador= | K43: Valor indicador= | L43: Valor indicador= | M43: Valor indicador= | N43: Valor indicador= | O43: Valor indicador= | P43: Valor indicador= | Q43: Valor indicador= | R43: Valor indicador= | S43: Valor indicador= | T43: Valor indicador= | U43: Valor indicador= | V43: Valor indicador= | W43: Valor indicador= | X43: Valor indicador= | Y43: Valor indicador= | Z43: Valor indicador= | AA43: Valor indicador= | AB43: Valor indicador= | AC43: Valor indicador= | AD43: Valor indicador=
...

Sheet Proyección
C1: PLANTILLA SIG COMPROMISOS INSTITUCIONALES | G1: DIVISIÓN PLANIFICACION Y DESARROLLO
G2: DEPARTAMENTO COMPROMISOS INSTITUCIONALES
G3: SUBDEPARTAMENTO GESTION DE INDICADORES INSTITUCIONALES
G5: Fecha: julio 2025
B6: Elaborado por: Analista de Gestión | C6: Revisado por: Jefa Subdepartamento Gestión de Indicadores Institucionales | G6: Aprobado por: Jefa Departamento Compromisos Institucionales
B7: PROYECCIONES
B8: Convenio de Desempeño Alta Dirección Pública
B9: Director Regional - Región de Coquimbo, Sr. Juan Paulo Garrido Piccioli
B10: Primer Período, tercer año julio 2025 - junio 2026
A11: INDICADOR | B11: INDICADOR | C11: FORMULA | D11: PONDERACIÓN | E11: Meta a julio 2025 | F11: Operandos | G11: Operandos Estimados Meta | H11: 45839 | I11: 45870 | J11: Acum. | K11: 45901 | L11: Acum. | M11: 45931 | N11: Acum. | O11: 45962 | P11: Acum. | Q11: 45992 | R11: Acum. | S11: 46023 | T11: Acum. | U11: 46054 | V11: Acum. | W11: 38777 | X11: Acum. | Y11: 46113 | Z11: Acum. | AA11: 46143 | AB11: Acum. | AC11: 46174 | AD11: Cumplimiento Efectivo a la fecha | AE11: % Cumplimiento de Meta
A13: ADP_DR04_04 | B13: 4.Porcentaje de líneas de acción implementadas del Plan de Calidad de Servicios en la región en el año t | C13: (Numero de lineas de accion implentadas del Plan de Calidad de Servicio en la región en el año t / Total de líneas de acción definidas en el Plan de calidad de Servicios en año t) *100) | D13: 0.2 | E13: 1 | F13: Numero de lineas de accion implentadas del Plan de Calidad de Servicio en la región en el año t | G13: Valor indicador= | H13: Valor indicador= | I13: Valor indicador= | J13: Valor indicador= | K13: Valor indicador= | L13: Valor indicador= | M13: Valor indicador= | N13: Valor indicador= | O13: Valor indicador= | P13: Valor indicador= | Q13: Valor indicador= | R13: Valor indicador= | S13: Valor indicador= | T13: Valor indicador= | U13: Valor indicador= | V13: Valor indicador= | W13: Valor indicador= | X13: Valor indicador= | Y13: Valor indicador= | Z13: Valor indicador= | AA13: Valor indicador= | AB13: Valor indicador= | AC13: Valor indicador= | AD13: Valor indicador=
G14: =IF(G16<>0,+G16/G18,0%) -> 1 | H14: =IF(H16<>0,+H16/H18,0%) -> 0 | I14: =IF(I16<>0,+I16/I18,0%) -> 0 | J14: =IF(J16<>0,ROUND(+J16/J18,4),0%) -> 0 | K14: =IF(K16<>0,+K16/K18,0%) -> 0 | L14: =IF(L16<>0,ROUND(+L16/L18,4),0%) -> 0 | M14: =IF(M16<>0,+M16/M18,0%) -> 0 | N14: =IF(N16<>0,ROUND(+N16/N18,4),0%) -> 0 | O14: =IF(O16<>0,+O16/O18,0%) -> 0 | P14: =IF(P16<>0,ROUND(+P16/P18,4),0%) -> 0 | Q14: =IF(Q16<>0,+Q16/Q18,0%) -> 0.66666667 | R14: =IF(R16<>0,ROUND(+R16/R18,4),0%) -> 0.6667 | S14: =IF(S16<>0,ROUND(+S16/S18,4),0%) -> 0 | T14: =IF(T16<>0,ROUND(+T16/T18,4),0%) -> 0.6667 | U14: =IF(U16<>0,ROUND(+U16/U18,4),0%) -> 0 | V14: =IF(V16<>0,ROUND(+V16/V18,4),0%) -> 0.6667 | W14: =IF(W16<>0,ROUND(+W16/W18,4),0%) -> 0 | X14: =IF(X16<>0,ROUND(+X16/X18,4),0%) -> 0.6667 | Y14: =IF(Y16<>0,ROUND(+Y16/Y18,4),0%) -> 0 | ... AC14: =IF(AC16<>0,ROUND(+AC16/AC18,4),0%) -> 0.3333 | AD14: =IF(AD16<>0,+AD16/AD18,0%) -> 1
G15: Operando 1= | H15: Operando 1= | I15: Operando 1= | J15: Operando 1= | K15: Operando 1= | L15: Operando 1= | M15: Operando 1= | N15: Operando 1= | O15: Operando 1= | P15: Operando 1= | Q15: Operando 1= | R15: Operando 1= | S15: Operando 1= | T15: Operando 1= | U15: Operando 1= | V15: Operando 1= | W15: Operando 1= | X15: Operando 1= | Y15: Operando 1= | Z15: Operando 1= | AA15: Operando 1= | AB15: Operando 1= | AC15: Operando 1= | AD15: Operando 1=
F16: Total de líneas de acción definidas en el Plan de calidad de Servicios en año t | G16: 3 | H16: 0 | I16: 0 | J16: =+H16+I16 -> 0 | K16: 0 | L16: =+J16+K16 -> 0 | M16: 0 | N16: =+L16+M16 -> 0 | O16: 0 | P16: =+N16+O16 -> 0 | Q16: 2 | R16: =+P16+Q16 -> 2 | S16: 0 | T16: =+R16+S16 -> 2 | U16: 0 | V16: =+T16+U16 -> 2 | W16: 0 | X16: =+V16+W16 -> 2 | Y16: 0 | Z16: =+X16+Y16 -> 2 | AA16: 0 | AB16: =+Z16+AA16 -> 2 | AC16: 1 | AD16: =AB16+AC16 -> 3 | AE16: =AD14/E13 -> 1
G17: Operando 2= | H17: Operando 2= | I17: Operando 2= | J17: Operando 2= | K17: Operando 2= | L17: Operando 2= | M17: Operando 2= | N17: Operando 2= | O17: Operando 2= | P17: Operando 2= | Q17: Operando 2= | R17: Operando 2= | S17: Operando 2= | T17: Operando 2= | U17: Operando 2= | V17: Operando 2= | W17: Operando 2= | X17: Operando 2= | Y17: Operando 2= | Z17: Operando 2= | AA17: Operando 2= | AB17: Operando 2= | AC17: Operando 2= | AD17: Operando 2=
G18: 3 | H18: 3 | I18: 3 | J18: =+I18 -> 3 | K18: 3 | L18: =+K18 -> 3 | M18: 3 | N18: =+M18 -> 3 | O18: 3 | P18: =+O18 -> 3 | Q18: 3 | R18: =+Q18 -> 3 | S18: 3 | T18: =+S18 -> 3 | U18: 3 | V18: =+U18 -> 3 | W18: 3 | X18: =+W18 -> 3 | Y18: 3 | Z18: =+Y18 -> 3 | AA18: 3 | AB18: =+AA18 -> 3 | AC18: 3 | AD18: =AC18 -> 3
A19: ADP_DR04_05 | B19: 5. Porcentaje de actividades cumplidas del Plan de difusión en materias de Estado Verde en el año t | C19: (Número de actividades cumplidas del Plan de difusión en materias de Estado Verde desarrolladas en la región en el año t / Número total de actividades cumplidas del Plan de difusión en materias de Estado Verde programados en la región en el año t)* 100 | D19: 0.1 | E19: 1 | F19: (Número de actividades cumplidas del Plan de difusión en materias de Estado Verde desarrolladas en la región en el año t | G19: Valor indicador= | H19: Valor indicador= | I19: Valor indicador= | J19: Valor indicador= | K19: Valor indicador= | L19: Valor indicador= | M19: Valor indicador= | N19: Valor indicador= | O19: Valor indicador= | P19: Valor indicador= | Q19: Valor indicador= | R19: Valor indicador= | S19: Valor indicador= | T19: Valor indicador= | U19: Valor indicador= | V19: Valor indicador= | W19: Valor indicador= | X19: Valor indicador= | Y19: Valor indicador= | Z19: Valor indicador= | AA19: Valor indicador= | AB19: Valor indicador= | AC19: Valor indicador= | AD19: Valor indicador=
G20: =IF(G22<>0,+G22/G24,0) -> 1 | H20: =IF(H22<>0,+H22/H24,0%) -> 0 | I20: =IF(I22<>0,+I22/I24,0%) -> 0 | J20: =IF(J22<>0,ROUND(+J22/J24,4),0%) -> 0 | K20: =IF(K22<>0,+K22/K24,0%) -> 0 | L20: =IF(L22<>0,ROUND(+L22/L24,4),0%) -> 0 | M20: =IF(M22<>0,+M22/M24,0%) -> 0 | N20: =IF(N22<>0,ROUND(+N22/N24,4),0%) -> 0 | O20: =IF(O22<>0,+O22/O24,0%) -> 0 | P20: =IF(P22<>0,ROUND(+P22/P24,4),0%) -> 0 | Q20: =IF(Q22<>0,+Q22/Q24,0%) -> 0 | R20: =IF(R22<>0,ROUND(+R22/R24,4),0%) -> 0 | S20: =IF(S22<>0,+S22/S24,0%) -> 0 | T20: =IF(T22<>0,ROUND(+T22/T24,4),0%) -> 0 | U20: =IF(U22<>0,+U22/U24,0%) -> 0 | V20: =IF(V22<>0,ROUND(+V22/V24,4),0%) -> 0 | W20: =IF(W22<>0,+W22/W24,0%) -> 0 | X20: =IF(X22<>0,ROUND(+X22/X24,4),0%) -> 0 | Y20: =IF(Y22<>0,+Y22/Y24,0%) -> 0 | Z20: =IF(Z22<>0,ROUND(+Z22/Z24,4),0%) -> 0 | AA20: =IF(AA22<>0,+AA22/AA24,0%) -> 0 | AB20: =IF(AB22<>0,ROUND(+AB22/AB24,4),0%) -> 0 | AC20: =IF(AC22<>0,+AC22/AC24,0%) -> 1 | AD20: =IF(AD22<>0,+AD22/AD24,0%) -> 1
G21: Operando 1= | H21: Operando 1= | I21: Operando 1= | J21: Operando 1= | K21: Operando 1= | L21: Operando 1= | M21: Operando 1= | N21: Operando 1= | O21: Operando 1= | P21: Operando 1= | Q21: Operando 1= | R21: Operando 1= | S21: Operando 1= | T21: Operando 1= | U21: Operando 1= | V21: Operando 1= | W21: Operando 1= | X21: Operando 1= | Y21: Operando 1= | Z21: Operando 1= | AA21: Operando 1= | AB21: Operando 1= | AC21: Operando 1= | AD21: Operando 1=
F22: Número total de actividades cumplidas del Plan de difusión en materias de Estado Verde programados en la región en el año t)* 100 | G22: 2 | H22: 0 | I22: 0 | J22: =H22+I22 -> 0 | K22: 0 | L22: =J22+K22 -> 0 | M22: 0 | N22: =L22+M22 -> 0 | O22: 0 | P22: =N22+O22 -> 0 | Q22: 0 | R22: =P22+Q22 -> 0 | S22: 0 | T22: =R22+S22 -> 0 | U22: 0 | V22: =T22+U22 -> 0 | W22: 0 | X22: =V22+W22 -> 0 | Y22: 0 | Z22: =X22+Y22 -> 0 | AA22: 0 | AB22: =Z22+AA22 -> 0 | AC22: 2 | AD22: =AB22+AC22 -> 2 | AE22: =AD20/E19 -> 1
G23: Operando 2= | H23: Operando 2= | I23: Operando 2= | J23: Operando 2= | K23: Operando 2= | L23: Operando 2= | M23: Operando 2= | N23: Operando 2= | O23: Operando 2= | P23: Operando 2= | Q23: Operando 2= | R23: Operando 2= | S23: Operando 2= | T23: Operando 2= | U23: Operando 2= | V23: Operando 2= | W23: Operando 2= | X23: Operando 2= | Y23: Operando 2= | Z23: Operando 2= | AA23: Operando 2= | AB23: Operando 2= | AC23: Operando 2= | AD23: Operando 2=
G24: 2 | H24: 2 | I24: 2 | J24: =I24 -> 2 | K24: 2 | L24: =K24 -> 2 | M24: 2 | N24: =M24 -> 2 | O24: 2 | P24: =O24 -> 2 | Q24: 2 | R24: =Q24 -> 2 | S24: 2 | T24: =S24 -> 2 | U24: 2 | V24: =U24 -> 2 | W24: 2 | X24: =W24 -> 2 | Y24: 2 | Z24: =Y24 -> 2 | AA24: 2 | AB24: =AA24 -> 2 | AC24: 2 | AD24: =AC24 -> 2
A25: ADP_DR04_07 | B25: 7. Porcentaje de funcionarios/as capacitados en la región en temáticas de Integridad en el | C25: (Sumatoria de funcionarios/as capacitados en la región en temáticas de Integridad en el año t / Dotación de funcionarios/as de la Región en el año t)*100 | D25: 0.1 | E25: 0.2 | F25: Sumatoria de funcionarios/as capacitados en la región en temáticas de Integridad en el año t | G25: Valor indicador= | H25: Valor indicador= | I25: Valor indicador= | J25: Valor indicador= | K25: Valor indicador= | L25: Valor indicador= | M25: Valor indicador= | N25: Valor indicador= | O25: Valor indicador= | P25: Valor indicador= | Q25: Valor indicador= | R25: Valor indicador= | S25: Valor indicador= | T25: Valor indicador= | U25: Valor indicador= | V25: Valor indicador= | W25: Valor indicador= | X25: Valor indicador= | Y25: Valor indicador= | Z25: Valor indicador= | AA25: Valor indicador= | AB25: Valor indicador= | AC25: Valor indicador= | AD25: Valor indicador=
G26: =IF(G28<>0,+G28/G30,0%) -> 0.2 | H26: =IF(H28<>0,+H28/H30,0%) -> 0 | I26: =IF(I28<>0,+I28/I30,0%) -> 0 | J26: =IF(J28<>0,ROUND(+J28/J30,4),0%) -> 0 | K26: =IF(K28<>0,+K28/K30,0%) -> 0 | L26: =IF(L28<>0,ROUND(+L28/L30,4),0%) -> 0 | M26: =IF(M28<>0,+M28/M30,0%) -> 0 | N26: =IF(N28<>0,ROUND(+N28/N30,4),0%) -> 0 | O26: =IF(O28<>0,+O28/O30,0%) -> 0 | P26: =IF(P28<>0,ROUND(+P28/P30,4),0%) -> 0 | Q26: =IF(Q28<>0,+Q28/Q30,0%) -> 0 | R26: =IF(R28<>0,ROUND(+R28/R30,4),0%) -> 0 | S26: =IF(S28<>0,+S28/S30,0%) -> 0 | T26: =IF(T28<>0,ROUND(+T28/T30,4),0%) -> 0 | U26: =IF(U28<>0,+U28/U30,0%) -> 0 | V26: =IF(V28<>0,ROUND(+V28/V30,4),0%) -> 0 | W26: =IF(W28<>0,+W28/W30,0%) -> 0 | X26: =IF(X28<>0,ROUND(+X28/X30,4),0%) -> 0 | Y26: =IF(Y28<>0,+Y28/Y30,0%) -> 0.2 | Z26: =IF(Z28<>0,ROUND(+Z28/Z30,4),0%) -> 0.2 | AA26: =IF(AA28<>0,+AA28/AA30,0%) -> 0 | AB26: =IF(AB28<>0,ROUND(+AB28/AB30,4),0%) -> 0.2 | AC26: =IF(AC28<>0,+AC28/AC30,0%) -> 0 | AD26: =IF(AD28<>0,ROUND(+AD28/AD30,4),0%) -> 0.2
G27: Operando 1= | H27: Operando 1= | I27: Operando 1= | J27: Operando 1= | K27: Operando 1= | L27: Operando 1= | M27: Operando 1= | N27: Operando 1= | O27: Operando 1= | P27: Operando 1= | Q27: Operando 1= | R27: Operando 1= | S27: Operando 1= | T27: Operando 1= | U27: Operando 1= | V27: Operando 1= | W27: Operando 1= | X27: Operando 1= | Y27: Operando 1= | Z27: Operando 1= | AA27: Operando 1= | AB27: Operando 1= | AC27: Operando 1= | AD27: Operando 1=
F28: Dotación de funcionarios/as de la Región en el año t)*100 | G28: 17.2 | H28: 0 | I28: 0 | J28: =+H28+I28 -> 0 | K28: 0 | L28: =+J28+K28 -> 0 | M28: 0 | N28: =+L28+M28 -> 0 | O28: 0 | P28: =+N28+O28 -> 0 | Q28: 0 | R28: =+P28+Q28 -> 0 | S28: 0 | T28: =+R28+S28 -> 0 | U28: 0 | V28: =+T28+U28 -> 0 | W28: 0 | X28: =+V28+W28 -> 0 | Y28: 17.2 | Z28: =+X28+Y28 -> 17.2 | AA28: 0 | AB28: =+Z28+AA28 -> 17.2 | AC28: 0 | AD28: =+AB28+AC28 -> 17.2
G29: Operando 2= | H29: Operando 2= | I29: Operando 2= | J29: Operando 2= | K29: Operando 2= | L29: Operando 2= | M29: Operando 2= | N29: Operando 2= | O29: Operando 2= | P29: Operando 2= | Q29: Operando 2= | R29: Operando 2= | S29: Operando 2= | T29: Operando 2= | U29: Operando 2= | V29: Operando 2= | W29: Operando 2= | X29: Operando 2= | Y29: Operando 2= | Z29: Operando 2= | AA29: Operando 2= | AB29: Operando 2= | AC29: Operando 2= | AD29: Operando 2=
G30: 86 | H30: 86 | I30: 86 | J30: 86 | K30: 86 | L30: 86 | M30: 86 | N30: 86 | O30: 86 | P30: 86 | Q30: 86 | R30: 86 | S30: 86 | T30: 86 | U30: 86 | V30: 86 | W30: 86 | X30: 86 | Y30: 86 | Z30: 86 | AA30: 86 | AB30: 86 | AC30: 86 | AD30: 86
A31: ADP_DR04_08 | B31: 8. Porcentaje de actividades cumplidas del Plan para generar iniciativas de innovación, en el año t | C31: (Sumatoria de actividades cumplidas del Plan para generar iniciativas de innovación, en el año t / Número total de actividades definidas en el Plan en el periodo) *100 | D31: 0.1 | E31: 1 | F31: Sumatoria de actividades cumplidas del Plan para generar iniciativas de innovación, en el año t | G31: Valor indicador= | H31: Valor indicador= | I31: Valor indicador= | J31: Valor indicador= | K31: Valor indicador= | L31: Valor indicador= | M31: Valor indicador= | N31: Valor indicador= | O31: Valor indicador= | P31: Valor indicador= | Q31: Valor indicador= | R31: Valor indicador= | S31: Valor indicador= | T31: Valor indicador= | U31: Valor indicador= | V31: Valor indicador= | W31: Valor indicador= | X31: Valor indicador= | Y31: Valor indicador= | Z31: Valor indicador= | AA31: Valor indicador= | AB31: Valor indicador= | AC31: Valor indicador= | AD31: Valor indicador=
G32: =IF(G34<>0,+G34/G36,0%) -> 1 | H32: =IF(H34<>0,+H34/H36,0%) -> 0 | I32: =IF(I34<>0,+I34/I36,0%) -> 0 | J32: =IF(J34<>0,+J34/J36,0%) -> 0 | K32: =IF(K34<>0,+K34/K36,0%) -> 0 | L32: =IF(L34<>0,+L34/L36,0%) -> 0 | M32: =IF(M34<>0,+M34/M36,0%) -> 0 | N32: =IF(N34<>0,+N34/N36,0%) -> 0 | ... AD32: =IF(AD34<>0,+AD34/AD36,0%) -> 1
G33: Operando 1= | H33: Operando 1= | J33: Operando 1= | K33: Operando 1= | L33: Operando 1= | M33: Operando 1= | N33: Operando 1= | O33: Operando 1= | P33: Operando 1= | Q33: Operando 1= | R33: Operando 1= | S33: Operando 1= | T33: Operando 1= | U33: Operando 1= | V33: Operando 1= | W33: Operando 1= | X33: Operando 1= | Y33: Operando 1= | Z33: Operando 1= | AA33: Operando 1= | AB33: Operando 1= | AC33: Operando 1= | AD33: Operando 1=
F34: Sumatoria total de actividades definidas en el Plan en el periodo | G34: 5 | H34: 0 | I34: 0 | J34: =+H34+I34 -> 0 | K34: 0 | L34: =+J34+K34 -> 0 | M34: 0 | N34: =+L34+M34 -> 0 | O34: 1 | P34: =+N34+O34 -> 1 | Q34: 1 | R34: =+P34+Q34 -> 2 | S34: 0 | T34: =+R34+S34 -> 2 | U34: 0 | V34: =+T34+U34 -> 2 | W34: 1 | X34: =+V34+W34 -> 3 | Y34: 1 | Z34: =+X34+Y34 -> 4 | AA34: 1 | AB34: =+Z34+AA34 -> 5 | AC34: 0 | AD34: =+AB34+AC34 -> 5 | AE34: =AD32/E31 -> 1
G35: Operando 2= | H35: Operando 2= | I35: Operando 2= | J35: Operando 2= | K35: Operando 2= | L35: Operando 2= | M35: Operando 2= | N35: Operando 2= | O35: Operando 2= | P35: Operando 2= | Q35: Operando 2= | R35: Operando 2= | S35: Operando 2= | T35: Operando 2= | U35: Operando 2= | V35: Operando 2= | W35: Operando 2= | X35: Operando 2= | Y35: Operando 2= | Z35: Operando 2= | AA35: Operando 2= | AB35: Operando 2= | AC35: Operando 2= | AD35: Operando 2=
G36: 5 | H36: 5 | I36: 5 | J36: =I36 -> 5 | K36: 5 | L36: =K36 -> 5 | M36: 5 | N36: =M36 -> 5 | O36: 5 | P36: =O36 -> 5 | Q36: 5 | R36: =Q36 -> 5 | S36: 5 | T36: =S36 -> 5 | U36: 5 | V36: =U36 -> 5 | W36: 5 | X36: =W36 -> 5 | Y36: 5 | Z36: =Y36 -> 5 | AA36: 5 | AB36: =AA36 -> 5 | AC36: 5 | AD36: =AC36 -> 5
A37: ADP_DR04_09 | B37: 9. Porcentaje de actividades cumplidas del Plan de Difusión de temáticas de Seguridad Social y otras en la comunidad en el año t | C37: (Sumatoria de actividades cumplidas del Plan de Difusión de temáticas de Seguridad Social y otras en la comunidad en el año t / N° total de actividades programadas del Plan en el año t) *100 | D37: 0.1 | E37: 1 | F37: (Sumatoria de actividades cumplidas del Plan de Difusión de temáticas de Seguridad Social y otras en la comunidad en el año t | G37: Valor indicador= | H37: Valor indicador= | I37: Valor indicador= | J37: Valor indicador= | K37: Valor indicador= | L37: Valor indicador= | M37: Valor indicador= | N37: Valor indicador= | O37: Valor indicador= | P37: Valor indicador= | Q37: Valor indicador= | R37: Valor indicador= | S37: Valor indicador= | T37: Valor indicador= | U37: Valor indicador= | V37: Valor indicador= | W37: Valor indicador= | X37: Valor indicador= | Y37: Valor indicador= | Z37: Valor indicador= | AA37: Valor indicador= | AB37: Valor indicador= | AC37: Valor indicador= | AD37: Valor indicador=
G38: =IF(G40<>0,+G40/G42,0%) -> 1 | H38: =IF(H40<>0,+H40/H42,0%) -> 0.1 | I38: =IF(I40<>0,+I40/I42,0%) -> 0.1 | J38: =IF(J40<>0,+J40/J42,0%) -> 0.2 | K38: =IF(K40<>0,+K40/K42,0%) -> 0.1 | L38: =IF(L40<>0,+L40/L42,0%) -> 0.3 | M38: =IF(M40<>0,+M40/M42,0%) -> 0 | N38: =IF(N40<>0,+N40/N42,0%) -> 0.3 | ... AD38: =IF(AD40<>0,+AD40/AD42,0%) -> 1
G39: Operando 1= | H39: Operando 1= | J39: Operando 1= | K39: Operando 1= | L39: Operando 1= | M39: Operando 1= | N39: Operando 1= | O39: Operando 1= | P39: Operando 1= | Q39: Operando 1= | R39: Operando 1= | S39: Operando 1= | T39: Operando 1= | U39: Operando 1= | V39: Operando 1= | W39: Operando 1= | X39: Operando 1= | Y39: Operando 1= | Z39: Operando 1= | AA39: Operando 1= | AB39: Operando 1= | AC39: Operando 1= | AD39: Operando 1=
F40: N° total de actividades programadas del Plan en el año t) *100 | G40: 10 | H40: 1 | I40: 1 | J40: =+H40+I40 -> 2 | K40: 1 | L40: =+J40+K40 -> 3 | M40: 0 | N40: =+L40+M40 -> 3 | O40: 0 | P40: =+N40+O40 -> 3 | Q40: 1 | R40: =+P40+Q40 -> 4 | S40: 2 | T40: =+R40+S40 -> 6 | U40: 1 | V40: =+T40+U40 -> 7 | W40: 1 | X40: =+V40+W40 -> 8 | Y40: 0 | Z40: =+X40+Y40 -> 8 | AA40: 1 | AB40: =+Z40+AA40 -> 9 | AC40: 1 | AD40: =+AB40+AC40 -> 10 | AE40: =AD38/E37 -> 1
G41: Operando 2= | H41: Operando 2= | I41: Operando 2= | J41: Operando 2= | K41: Operando 2= | L41: Operando 2= | M41: Operando 2= | N41: Operando 2= | O41: Operando 2= | P41: Operando 2= | Q41: Operando 2= | R41: Operando 2= | S41: Operando 2= | T41: Operando 2= | U41: Operando 2= | V41: Operando 2= | W41: Operando 2= | X41: Operando 2= | Y41: Operando 2= | Z41: Operando 2= | AA41: Operando 2= | AB41: Operando 2= | AC41: Operando 2= | AD41: Operando 2=
G42: 10 | H42: 10 | I42: 10 | J42: =I42 -> 10 | K42: 10 | L42: =K42 -> 10 | M42: 10 | N42: =M42 -> 10 | O42: 10 | P42: =O42 -> 10 | Q42: 10 | R42: =Q42 -> 10 | S42: 10 | T42: =S42 -> 10 | U42: 10 | V42: =U42 -> 10 | W42: 10 | X42: =W42 -> 10 | Y42: 10 | Z42: =Y42 -> 10 | AA42: 10 | AB42: =AA42 -> 10 | AC42: 10 | AD42: =AC42 -> 10
...

Sheet Consolidado
A1: CONVENIO DE DESEMPEÑO ALTA DIRECCIÓN PÚBLICA
A3: Director Regional - Región de Coquimbo Sr. Juan Paulo Garrido Piccioli (julio 2025 - junio 2026)
A5: Indicador | B5: Fórmula de Cálculo | C5: Pond. | D5: Meta junio 2026 | E5: Valores según Fórmula de Cálculo | G5: % Cumpli- miento | H5: Total Pond. | I5: Proyección
E7: Operandos | F7: Efectivo a enero 2026 | I7: Resultado a enero 2026 | J7: % Cumpli- miento | K7: Pond.
A8: 1.Porcentaje de líneas de acción implementadas del Plan de Calidad de Servicios en la región en el año t | B8: (Numero de lineas de accion implentadas del Plan de Calidad de Servicio en la región en el año t / Total de líneas de acción definidas en el Plan de calidad de Servicios en año t) *100) | C8: 0.2 | D8: 1 | E8: =+'[1]Plantilla SIG'!AB16 -> 2 | F8: =+'[1]Plantilla SIG'!AB14 -> 0.66666667 | G8: =F8/D8 -> 0.66666667 | H8: =IF(G8>100%,C8,G8*C8) -> 0.13333333 | I8: =+[1]Proyección!R14 -> 0.6667 | J8: =+I8/D8 -> 0.6667 | K8: =IF(J8>100%,C8,J8*C8) -> 0.13334
E9: =+'[1]Plantilla SIG'!AB18 -> 3 | H9: =IF(G9>100%,D9,G9*D9) -> 0 | K9: =IF(J9>100%,G9,J9*G9) -> 0
A10: 2. Porcentaje de actividades cumplidas del Plan de difusión en materias de Estado Verde en el año t | B10: mero de actividades cumplidas del Plan de difusión en materias de Estado Verde desarrolladas en la región en el año t / Número total de actividades cumplidas del Plan de difusión en materias de Estado Verde programados en la región en el año t)* 100 | C10: 0.1 | D10: 1 | E10: =+'[1]Plantilla SIG'!AB22 -> 0 | F10: =+'[1]Plantilla SIG'!AC22 -> 0 | G10: =F10/D10 -> 0 | H10: =IF(G10>100%,C10,G10*C10) -> 0 | I10: =+[1]Proyección!R20 -> 0 | J10: =+I10/D10 -> 0 | K10: =IF(J10>100%,C10,J10*C10) -> 0
E11: =+'[1]Plantilla SIG'!AB24 -> 2 | H11: =IF(G11>100%,D11,G11*D11) -> 0 | K11: =IF(J11>100%,G11,J11*G11) -> 0
A12: 3. Porcentaje de funcionarios/as capacitados en la región en temáticas de Integridad en el año t | B12: (Sumatoria de funcionarios/as capacitados en la región en temáticas de Integridad en el año t / Dotación de funcionarios/as de la Región en el año t)*100 | C12: 0.1 | D12: 1 | E12: =+'[1]Plantilla SIG'!AB28 -> 0 | F12: =+'[1]Plantilla SIG'!AB26 -> 0 | G12: =F12/D12 -> 0 | H12: =IF(G12>100%,C12,G12*C12) -> 0 | I12: =+[1]Proyección!R26 -> 0 | J12: =+I12/D12 -> 0 | K12: =IF(J12>100%,C12,J12*C12) -> 0
E13: =+'[1]Plantilla SIG'!AB30 -> 86 | H13: =IF(G13>100%,D13,G13*D13) -> 0 | K13: =IF(J13>100%,G13,J13*G13) -> 0
A14: 4. Porcentaje de actividades cumplidas del Plan para generar iniciativas de innovación, en el año t | B14: (Sumatoria de actividades cumplidas del Plan para generar iniciativas de innovación, en el año t / Número total de actividades definidas en el Plan en el periodo) *100 | C14: 0.1 | D14: 0.6 | E14: ='[1]Plantilla SIG'!AB34 -> 2 | F14: ='[1]Plantilla SIG'!AB32 -> 0.4 | G14: =F14/D14 -> 0.66666667 | H14: =IF(G14>100%,C14,G14*C14) -> 0.066666667 | I14: =+[1]Proyección!R32 -> 0.4 | J14: =+I14/D14 -> 0.66666667 | K14: =IF(J14>100%,C14,J14*C14) -> 0.066666667
E15: ='[1]Plantilla SIG'!AB36 -> 5 | H15: =IF(G15>100%,D15,G15*D15) -> 0 | K15: =IF(J15>100%,G15,J15*G15) -> 0
A16: 5. Porcentaje de actividades cumplidas del Plan de Difusión de temáticas de Seguridad Social y otras en la comunidad en el año t | B16: (Sumatoria de actividades cumplidas del Plan de Difusión de temáticas de Seguridad Social y otras en la comunidad en el año t / N° total de actividades programadas del Plan en el año t) *100 | C16: 0.2 | D16: 1 | E16: ='[1]Plantilla SIG'!AB40 -> 6 | F16: ='[1]Plantilla SIG'!AB38 -> 0.6 | G16: =F16/D16 -> 0.6 | H16: =IF(G16>100%,C16,G16*C16) -> 0.12 | I16: =+[1]Proyección!R38 -> 0.6 | J16: =+I16/D16 -> 0.6 | K16: =IF(J16>100%,C16,J16*C16) -> 0.12
E17: ='[1]Plantilla SIG'!AB42 -> 10 | H17: =IF(G17>100%,D17,G17*D17) -> 0 | K17: =IF(J17>100%,G17,J17*G17) -> 0
A18: 7. Porcentaje de actividades cumplidas del plan de acción para la Satisfacción Laboral en el año t | B18: (Sumatoria de actividades cumplidas del plan de acción para la Satisfacción Laboral en al año t / N° total de actividades programadas del plan de acción para la Satisfacción Laboral en el año t)*100 | C18: 0.1 | D18: 1 | E18: ='[1]Plantilla SIG'!AB46 -> 1 | F18: ='[1]Plantilla SIG'!AC46 -> 0.25 | G18: =F18/D18 -> 0.25 | H18: =IF(G18>100%,C18,G18*C18) -> 0.025 | I18: =+[1]Proyección!R44 -> 0.25 | J18: =+I18/D18 -> 0.25 | K18: =IF(J18>100%,C18,J18*C18) -> 0.025
E19: ='[1]Plantilla SIG'!AB48 -> 4 | H19: =IF(G19>100%,D19,G19*D19) -> 0 | K19: =IF(J19>100%,G19,J19*G19) -> 0
A20: 8.Porcentaje de actividades realizadas de acuerdo al plan para mejorar la eficiencia y eficacia de la gestión de continuidad operacional en Sucursal La Serena . | B20: (N° de actividades cumplidas de acuerdo al plan para mejorar la eficiencia y eficacia de la gestión de continuidad operacional en La Serena / N° de actividades definidas en el plan l para mejorar la eficiencia y eficacia de la gestión de continuidad operacional en Sucursal La Serena) *100 | C20: 0.2 | D20: 1 | E20: ='[1]Plantilla SIG'!AB52 -> 2 | F20: ='[1]Plantilla SIG'!AC52 -> 0.66666667 | G20: =F20/D20 -> 0.66666667 | H20: =IF(G20>100%,C20,G20*C20) -> 0.13333333 | I20: =+[1]Proyección!R50 -> 0.66666667 | J20: =+I20/D20 -> 0.66666667 | K20: =IF(J20>100%,C20,J20*C20) -> 0.13333333
E21: ='[1]Plantilla SIG'!AB54 -> 3 | H21: =IF(G21>100%,D21,G21*D21) -> 0 | K21: =IF(J21>100%,G21,J21*G21) -> 0
E22: % de cumplimiernto informado | H22: =H8+H10+H12+H14+H16+H20+H18 -> 0.47833333 | K22: =+SUM(K8:K21) -> 0.47834
E23: % de cumplimiento por informar | H23: =+H24-H22 -> 0.52166667
E24: % de cumplimiento esperado | H24: 1
