Workbook

Sheet Plantilla SIG
C1: PLANTILLA SIG COMPROMISOS INSTITUCIONALES | G1: DIVISIÓN PLANIFICACION Y DESARROLLO
G2: DEPARTAMENTO COMPROMISOS INSTITUCIONALES
G3: SUBDEPARTAMENTO GESTION DE INDICADORES INSTITUCIONALES
G5: Fecha: noviembre 2025
B6: Elaborado por: Analista de Gestión | C6: Revisado por: Jefa Subdepartamento Gestión de Indicadores Institucionales | G6: Aprobado por: Jefa Departamento Compromisos Institucionales
B8: Convenio de Desempeño Alta Dirección Pública
B9: Jefe Departamento Gestión Beneficios, Sr. Jorge Zúñiga Martínez
B10: Primer Período, tercer año agosto 2025 - julio 2026
A11: NUMERO | B11: INDICADOR | C11: FORMULA | D11: PONDERACIÖN | E11: Meta | F11: Operandos | G11: Operandos Estimados Meta | H11: 45870 | I11: 45901 | J11: Acum. | K11: 45931 | L11: Acum. | M11: 45962 | N11: Acum. | O11: 45992 | P11: Acum. | Q11: 46023 | R11: Acum. | S11: 46054 | T11: Acum. | U11: 46082 | V11: Acum. | W11: 46113 | X11: Acum. | Y11: 46143 | Z11: Acum. | AA11: 46174 | AB11: Acum. | AC11: 46204 | AD11: Cumplimiento Efectivo a la fecha | AE11: % Cumplimiento de Meta
A13: ADP_BENEF_01 | B13: 1. Porcentaje de actividades cumplidos del plan para la aplicación de la encuesta de Satisfacción Neta de usuarios | C13: (Sumatoria de actividades cumplidas del plan para la aplicación de la encuesta de Satisfacción Neta de usuarios / Número total de actividades definidas en el plan para la aplicación de la encuesta de Satisfacción Neta de usuarios) *100 | D13: 0.15 | E13: 1 | F13: Sumatoria de actividades cumplidas del plan para la aplicación de la encuesta de Satisfacción Neta de usuarios | G13: Valor indicador= | H13: Valor indicador= | I13: Valor indicador= | J13: Valor indicador= | K13: Valor indicador= | L13: Valor indicador= | M13: Valor indicador= | N13: Valor indicador= | O13: Valor indicador= | P13: Valor indicador= | Q13: Valor indicador= | R13: Valor indicador= | S13: Valor indicador= | T13: Valor indicador= | U13: Valor indicador= | V13: Valor indicador= | W13: Valor indicador= | X13: Valor indicador= | Y13: Valor indicador= | Z13: Valor indicador= | AA13: Valor indicador= | AB13: Valor indicador= | AC13: Valor indicador= | AD13: Valor indicador=
G14: =IF(G16<>0,ROUND(+G16/G18,4),0%) -> 1 | H14: =IF(H16<>0,ROUND(+H16/H18,4),0%) -> 0.25 | I14: =IF(I16<>0,ROUND(+I16/I18,4),0%) -> 0.25 | J14: =IF(J16<>0,ROUND(+J16/J18,4),0%) -> 0.5 | K14: =IF(K16<>0,ROUND(+K16/K18,4),0%) -> 0.25 | L14: =IF(L16<>0,ROUND(+L16/L18,4),0%) -> 0.75 | M14: =IF(M16<>0,ROUND(+M16/M18,4),0%) -> 0 | N14: =IF(N16<>0,ROUND(+N16/N18,4),0%) -> 0.75 | ... AD14: =IF(AD16<>0,ROUND(+AD16/AD18,4),0%) -> 1
G15: Operando 1= | H15: Operando 1= | I15: Operando 1= | J15: Operando 1= | K15: Operando 1= | L15: Operando 1= | M15: Operando 1= | N15: Operando 1= | O15: Operando 1= | P15: Operando 1= | Q15: Operando 1= | R15: Operando 1= | S15: Operando 1= | T15: Operando 1= | U15: Operando 1= | V15: Operando 1= | W15: Operando 1= | X15: Operando 1= | Y15: Operando 1= | Z15: Operando 1= | AA15: Operando 1= | AB15: Operando 1= | AC15: Operando 1= | AD15: Operando 1=
F16: Número total de actividades definidas en el plan para la aplicación de la encuesta de Satisfacción Neta de usuarios | G16: 4 | H16: 1 | I16: 1 | J16: =+H16+I16 -> 2 | K16: 1 | L16: =+J16+K16 -> 3 | N16: =+L16+M16 -> 3 | O16: 1 | P16: =+N16+O16 -> 4 | Q16: 0 | R16: =+P16+Q16 -> 4 | T16: =+R16+S16 -> 4 | V16: =+T16+U16 -> 4 | X16: =+V16+W16 -> 4 | Z16: =+X16+Y16 -> 4 | AB16: =+Z16+AA16 -> 4 | AD16: =+AB16+AC16 -> 4 | AE16: =AD14/E13 -> 1
G17: Operando 2= | H17: Operando 2= | I17: Operando 2= | J17: Operando 2= | K17: Operando 2= | L17: Operando 2= | M17: Operando 2= | N17: Operando 2= | O17: Operando 2= | P17: Operando 2= | Q17: Operando 2= | R17: Operando 2= | S17: Operando 2= | T17: Operando 2= | U17: Operando 2= | V17: Operando 2= | W17: Operando 2= | X17: Operando 2= | Y17: Operando 2= | Z17: Operando 2= | AA17: Operando 2= | AB17: Operando 2= | AC17: Operando 2= | AD17: Operando 2=
G18: 4 | H18: 4 | I18: 4 | J18: =I18 -> 4 | K18: 4 | L18: =K18 -> 4 | M18: 4 | N18: 4 | O18: 4 | P18: =O18 -> 4 | Q18: 4 | R18: =Q18 -> 4 | S18: 4 | T18: =S18 -> 4 | U18: 4 | V18: =U18 -> 4 | W18: 4 | X18: =W18 -> 4 | Y18: 4 | Z18: =Y18 -> 4 | AA18: 4 | AB18: =AA18 -> 4 | AC18: 4 | AD18: =AC18 -> 4
A19: ADP_BENEF_02 | B19: 2. Porcentaje de proyectos priorizados por el Depto. de Gestión de Beneficios finalizados al año t | C19: (Sumatoria de proyectos priorizados por el Depto. de Gestión de Beneficios finalizados al año t / Número total de proyectos priorizados por el Depto. de Gestión de Beneficios planificados para el periodo) *100 | D19: 0.15 | E19: 1 | F19: Sumatoria de proyectos priorizados por el Depto. de Gestión de Beneficios finalizados al año t | G19: Valor indicador= | H19: Valor indicador= | I19: Valor indicador= | J19: Valor indicador= | K19: Valor indicador= | L19: Valor indicador= | M19: Valor indicador= | N19: Valor indicador= | O19: Valor indicador= | P19: Valor indicador= | Q19: Valor indicador= | R19: Valor indicador= | S19: Valor indicador= | T19: Valor indicador= | U19: Valor indicador= | V19: Valor indicador= | W19: Valor indicador= | X19: Valor indicador= | Y19: Valor indicador= | Z19: Valor indicador= | AA19: Valor indicador= | AB19: Valor indicador= | AC19: Valor indicador= | AD19: Valor indicador=
G20: =IF(G22<>0,ROUND(+G22/G24,4),0%) -> 1 | H20: =IF(H22<>0,ROUND(+H22/H24,4),0%) -> 0 | I20: =IF(I22<>0,ROUND(+I22/I24,4),0%) -> 0 | J20: =IF(J22<>0,ROUND(+J22/J24,4),0%) -> 0 | K20: =IF(K22<>0,ROUND(+K22/K24,4),0%) -> 0 | L20: =IF(L22<>0,ROUND(+L22/L24,4),0%) -> 0 | M20: =IF(M22<>0,ROUND(+M22/M24,4),0%) -> 0 | N20: =IF(N22<>0,ROUND(+N22/N24,4),0%) -> 0 | ... AD20: =IF(AD22<>0,ROUND(+AD22/AD24,4),0%) -> 0
G21: Operando 1= | H21: Operando 1= | I21: Operando 1= | J21: Operando 1= | K21: Operando 1= | L21: Operando 1= | M21: Operando 1= | N21: Operando 1= | O21: Operando 1= | P21: Operando 1= | Q21: Operando 1= | R21: Operando 1= | S21: Operando 1= | T21: Operando 1= | U21: Operando 1= | V21: Operando 1= | W21: Operando 1= | X21: Operando 1= | Y21: Operando 1= | Z21: Operando 1= | AA21: Operando 1= | AB21: Operando 1= | AC21: Operando 1= | AD21: Operando 1=
F22: Número total de proyectos priorizados por el Depto. de Gestión de Beneficios planificados para el periodo | G22: 1 | J22: =+H22+I22 -> 0 | L22: =+J22+K22 -> 0 | N22: =+L22+M22 -> 0 | O22: 0 | P22: =+N22+O22 -> 0 | Q22: 0 | R22: =+P22+Q22 -> 0 | T22: =+R22+S22 -> 0 | V22: =+T22+U22 -> 0 | X22: =+V22+W22 -> 0 | Z22: =+X22+Y22 -> 0 | AB22: =+Z22+AA22 -> 0 | AD22: =AB22+AC22 -> 0 | AE22: =AD20/E19 -> 0
G23: Operando 2= | H23: Operando 2= | I23: Operando 2= | J23: Operando 2= | K23: Operando 2= | L23: Operando 2= | M23: Operando 2= | N23: Operando 2= | O23: Operando 2= | P23: Operando 2= | Q23: Operando 2= | R23: Operando 2= | S23: Operando 2= | T23: Operando 2= | U23: Operando 2= | V23: Operando 2= | W23: Operando 2= | X23: Operando 2= | Y23: Operando 2= | Z23: Operando 2= | AA23: Operando 2= | AB23: Operando 2= | AC23: Operando 2= | AD23: Operando 2=
G24: 1 | H24: 1 | I24: 1 | J24: =I24 -> 1 | K24: 1 | L24: =K24 -> 1 | M24: 1 | N24: =M24 -> 1 | O24: 1 | P24: =O24 -> 1 | Q24: 1 | R24: =Q24 -> 1 | S24: 1 | T24: =S24 -> 1 | U24: 1 | V24: =U24 -> 1 | W24: 1 | X24: =W24 -> 1 | Y24: 1 | Z24: =Y24 -> 1 | AA24: 1 | AB24: =AA24 -> 1 | AC24: 1 | AD24: 1
A25: ADP_BENEF_03 | B25: 3. Porcentaje de actividades cumplidas del plan de prevención y control de eventos de riesgo derivados de los procesos claves en el año t | C25: (Sumatoria de actividades cumplidas del plan de prevención y control de eventos de riesgo derivados de los procesos claves en el año t / Sumatoria de actividades definidas en el plan en el año t) *100 | D25: 0.2 | E25: 1 | F25: Sumatoria de actividades cumplidas del plan de prevención y control de eventos de riesgo derivados de los procesos claves en el año t | G25: Valor indicador= | H25: Valor indicador= | I25: Valor indicador= | J25: Valor indicador= | K25: Valor indicador= | L25: Valor indicador= | M25: Valor indicador= | N25: Valor indicador= | O25: Valor indicador= | P25: Valor indicador= | Q25: Valor indicador= | R25: Valor indicador= | S25: Valor indicador= | T25: Valor indicador= | U25: Valor indicador= | V25: Valor indicador= | W25: Valor indicador= | X25: Valor indicador= | Y25: Valor indicador= | Z25: Valor indicador= | AA25: Valor indicador= | AB25: Valor indicador= | AC25: Valor indicador= | AD25: Valor indicador=
G26: =IF(G28<>0,ROUND(+G28/G30,4),0%) -> 1 | H26: =IF(H28<>0,ROUND(+H28/H30,4),0%) -> 0 | I26: =IF(I28<>0,ROUND(+I28/I30,4),0%) -> 0 | J26: =IF(J28<>0,ROUND(+J28/J30,4),0%) -> 0 | K26: =IF(K28<>0,ROUND(+K28/K30,4),0%) -> 0 | L26: =IF(L28<>0,ROUND(+L28/L30,4),0%) -> 0 | M26: =IF(M28<>0,ROUND(+M28/M30,4),0%) -> 0.2 | N26: =IF(N28<>0,ROUND(+N28/N30,4),0%) -> 0.2 | ... AD26: =IF(AD28<>0,ROUND(+AD28/AD30,4),0%) -> 0.2
G27: Operando 1= | H27: Operando 1= | I27: Operando 1= | J27: Operando 1= | K27: Operando 1= | L27: Operando 1= | M27: Operando 1= | N27: Operando 1= | O27: Operando 1= | P27: Operando 1= | Q27: Operando 1= | R27: Operando 1= | S27: Operando 1= | T27: Operando 1= | U27: Operando 1= | V27: Operando 1= | W27: Operando 1= | X27: Operando 1= | Y27: Operando 1= | Z27: Operando 1= | AA27: Operando 1= | AB27: Operando 1= | AC27: Operando 1= | AD27: Operando 1=
F28: Sumatoria de actividades definidas en el plan en el año t | G28: 5 | J28: =+H28+I28 -> 0 | L28: =+J28+K28 -> 0 | M28: 1 | N28: =+L28+M28 -> 1 | O28: 0 | P28: =+N28+O28 -> 1 | Q28: 0 | R28: =+P28+Q28 -> 1 | T28: =+R28+S28 -> 1 | V28: =+T28+U28 -> 1 | X28: =+V28+W28 -> 1 | Z28: =+X28+Y28 -> 1 | AB28: =+Z28+AA28 -> 1 | AD28: =+AB28+AC28 -> 1 | AE28: =AD26/E25 -> 0.2
G29: Operando 2= | H29: Operando 2= | I29: Operando 2= | J29: Operando 2= | K29: Operando 2= | L29: Operando 2= | M29: Operando 2= | N29: Operando 2= | O29: Operando 2= | P29: Operando 2= | Q29: Operando 2= | R29: Operando 2= | S29: Operando 2= | T29: Operando 2= | U29: Operando 2= | V29: Operando 2= | W29: Operando 2= | X29: Operando 2= | Y29: Operando 2= | Z29: Operando 2= | AA29: Operando 2= | AB29: Operando 2= | AC29: Operando 2= | AD29: Operando 2=
G30: 5 | H30: 5 | I30: 5 | J30: =I30 -> 5 | K30: 5 | L30: =K30 -> 5 | M30: 5 | N30: =M30 -> 5 | O30: 5 | P30: =O30 -> 5 | Q30: 5 | R30: =Q30 -> 5 | S30: 5 | T30: =S30 -> 5 | U30: 5 | V30: =U30 -> 5 | W30: 5 | X30: =W30 -> 5 | Y30: 5 | Z30: =Y30 -> 5 | AA30: 5 | AB30: =AA30 -> 5 | AC30: 5 | AD30: =AC30 -> 5
A31: ADP_BENEF_04 | B31: 4. Porcentaje de actividades cumplidas del plan de trabajo anual para mejorar la Satisfacción Laboral el año t | C31: (Sumatoria de actividades cumplidas del plan de trabajo anual para mejorar la Satisfacción Laboral en el año t / Nº total de actividades planificadas del plan de trabajo anual para mejorar la Satisfacción Laboral en el año t) *100 | D31: 0.15 | E31: 1 | F31: Sumatoria de actividades cumplidas del plan de trabajo anual para mejorar la Satisfacción Laboral en el año t | G31: Valor indicador= | H31: Valor indicador= | I31: Valor indicador= | J31: Valor indicador= | K31: Valor indicador= | L31: Valor indicador= | M31: Valor indicador= | N31: Valor indicador= | O31: Valor indicador= | P31: Valor indicador= | Q31: Valor indicador= | R31: Valor indicador= | S31: Valor indicador= | T31: Valor indicador= | U31: Valor indicador= | V31: Valor indicador= | W31: Valor indicador= | X31: Valor indicador= | Y31: Valor indicador= | Z31: Valor indicador= | AA31: Valor indicador= | AB31: Valor indicador= | AC31: Valor indicador= | AD31: Valor indicador=
G32: =IF(G34<>0,ROUND(+G34/G36,4),0%) -> 1 | H32: =IF(H34<>0,ROUND(+H34/H36,4),0%) -> 0 | I32: =IF(I34<>0,ROUND(+I34/I36,4),0%) -> 0 | J32: =IF(J34<>0,ROUND(+J34/J36,4),0%) -> 0 | K32: =IF(K34<>0,ROUND(+K34/K36,4),0%) -> 0 | L32: =IF(L34<>0,ROUND(+L34/L36,4),0%) -> 0 | M32: =IF(M34<>0,ROUND(+M34/M36,4),0%) -> 0 | N32: =IF(N34<>0,ROUND(+N34/N36,4),0%) -> 0 | ... AD32: =IF(AD34<>0,ROUND(+AD34/AD36,4),0%) -> 0.5
G33: Operando 1= | H33: Operando 1= | J33: Operando 1= | K33: Operando 1= | L33: Operando 1= | M33: Operando 1= | N33: Operando 1= | O33: Operando 1= | P33: Operando 1= | Q33: Operando 1= | R33: Operando 1= | S33: Operando 1= | T33: Operando 1= | U33: Operando 1= | V33: Operando 1= | W33: Operando 1= | X33: Operando 1= | Y33: Operando 1= | Z33: Operando 1= | AA33: Operando 1= | AB33: Operando 1= | AC33: Operando 1= | AD33: Operando 1=
F34: Nº total de actividades planificadas del plan de trabajo anual para mejorar la Satisfacción Laboral en el año t | G34: 4 | J34: =+H34+I34 -> 0 | L34: =+J34+K34 -> 0 | M34: 0 | N34: =+L34+M34 -> 0 | O34: 1 | P34: =+N34+O34 -> 1 | Q34: 1 | R34: =+P34+Q34 -> 2 | T34: =+R34+S34 -> 2 | V34: =+T34+U34 -> 2 | X34: =+V34+W34 -> 2 | Z34: =+X34+Y34 -> 2 | AB34: =+Z34+AA34 -> 2 | AD34: =+AB34+AC34 -> 2 | AE34: =AD32/E31 -> 0.5
G35: Operando 2= | H35: Operando 2= | I35: Operando 2= | J35: Operando 2= | K35: Operando 2= | L35: Operando 2= | M35: Operando 2= | N35: Operando 2= | O35: Operando 2= | P35: Operando 2= | Q35: Operando 2= | R35: Operando 2= | S35: Operando 2= | T35: Operando 2= | U35: Operando 2= | V35: Operando 2= | W35: Operando 2= | X35: Operando 2= | Y35: Operando 2= | Z35: Operando 2= | AA35: Operando 2= | AB35: Operando 2= | AC35: Operando 2= | AD35: Operando 2=
G36: 4 | H36: 4 | I36: 4 | J36: =I36 -> 4 | K36: 4 | L36: =K36 -> 4 | M36: 4 | N36: =M36 -> 4 | O36: 4 | P36: =O36 -> 4 | Q36: 4 | R36: =Q36 -> 4 | S36: 4 | T36: =S36 -> 4 | U36: 4 | V36: =U36 -> 4 | W36: 4 | X36: =W36 -> 4 | Y36: 4 | Z36: =Y36 -> 4 | AA36: 4 | AB36: =AA36 -> 4 | AC36: 4 | AD36: =AC36 -> 4
A37: ADP_BENEF_05 | B37: 5. Porcentaje de hitos cumplidos del Plan de Gestión del Conocimiento de Cargos Críticos | C37: (Sumatoria del cumplimiento de hitos del Plan de Gestión del Conocimiento comprometidos en el período / Nº total de hitos planificados del plan de Gestión del Conocimiento en el periodo) *100 | D37: 0.15 | E37: 1 | F37: Sumatoria del cumplimiento de hitos del Plan de Gestión del Conocimiento comprometidos en el período | G37: Valor indicador= | H37: Valor indicador= | I37: Valor indicador= | J37: Valor indicador= | K37: Valor indicador= | L37: Valor indicador= | M37: Valor indicador= | N37: Valor indicador= | O37: Valor indicador= | P37: Valor indicador= | Q37: Valor indicador= | R37: Valor indicador= | S37: Valor indicador= | T37: Valor indicador= | U37: Valor indicador= | V37: Valor indicador= | W37: Valor indicador= | X37: Valor indicador= | Y37: Valor indicador= | Z37: Valor indicador= | AA37: Valor indicador= | AB37: Valor indicador= | AC37: Valor indicador= | AD37: Valor indicador=
G38: =IF(G40<>0,ROUND(+G40/G42,4),0%) -> 1 | H38: =IF(H40<>0,ROUND(+H40/H42,4),0%) -> 0 | I38: =IF(I40<>0,ROUND(+I40/I42,4),0%) -> 0 | J38: =IF(J40<>0,ROUND(+J40/J42,4),0%) -> 0 | K38: =IF(K40<>0,ROUND(+K40/K42,4),0%) -> 0 | L38: =IF(L40<>0,ROUND(+L40/L42,4),0%) -> 0 | M38: =IF(M40<>0,ROUND(+M40/M42,4),0%) -> 0 | N38: =IF(N40<>0,ROUND(+N40/N42,4),0%) -> 0 | ... AD38: =IF(AD40<>0,ROUND(+AD40/AD42,4),0%) -> 0.5
G39: Operando 1= | H39: Operando 1= | J39: Operando 1= | K39: Operando 1= | L39: Operando 1= | M39: Operando 1= | N39: Operando 1= | O39: Operando 1= | P39: Operando 1= | Q39: Operando 1= | R39: Operando 1= | S39: Operando 1= | T39: Operando 1= | U39: Operando 1= | V39: Operando 1= | W39: Operando 1= | X39: Operando 1= | Y39: Operando 1= | Z39: Operando 1= | AA39: Operando 1= | AB39: Operando 1= | AC39: Operando 1= | AD39: Operando 1=
F40: Nº total de hitos planificados del plan de Gestión del Conocimiento en el periodo | G40: 2 | J40: =+H40+I40 -> 0 | L40: =+J40+K40 -> 0 | M40: 0 | N40: =+L40+M40 -> 0 | O40: 0 | P40: =+N40+O40 -> 0 | Q40: 1 | R40: =+P40+Q40 -> 1 | T40: =+R40+S40 -> 1 | V40: =+T40+U40 -> 1 | X40: =+V40+W40 -> 1 | Z40: =+X40+Y40 -> 1 | AB40: =+Z40+AA40 -> 1 | AD40: =+AB40+AC40 -> 1 | AE40: =AD38/E37 -> 0.5
G41: Operando 2= | H41: Operando 2= | I41: Operando 2= | J41: Operando 2= | K41: Operando 2= | L41: Operando 2= | M41: Operando 2= | N41: Operando 2= | O41: Operando 2= | P41: Operando 2= | Q41: Operando 2= | R41: Operando 2= | S41: Operando 2= | T41: Operando 2= | U41: Operando 2= | V41: Operando 2= | W41: Operando 2= | X41: Operando 2= | Y41: Operando 2= | Z41: Operando 2= | AA41: Operando 2= | AB41: Operando 2= | AC41: Operando 2= | AD41: Operando 2=
G42: 2 | H42: 2 | I42: 2 | J42: =I42 -> 2 | K42: 2 | L42: =K42 -> 2 | M42: 2 | N42: =M42 -> 2 | O42: 2 | P42: =O42 -> 2 | Q42: 2 | R42: =Q42 -> 2 | S42: 2 | T42: =S42 -> 2 | U42: 2 | V42: =U42 -> 2 | W42: 2 | X42: =W42 -> 2 | Y42: 2 | Z42: =Y42 -> 2 | AA42: 2 | AB42: =AA42 -> 2 | AC42: 2 | AD42: =AC42 -> 2
A43: ADP_BENEF_06 | B43: 6. Porcentaje de indicadores de desempeño por subproceso o proceso implementados en el periodo t. | C43: (Nº de indicadores de desempeño por subprocesos implementados en el periodo t / Nº total de indicadores planificados para implementar en el periodo) *100 | D43: 0.1 | E43: 1 | F43: Nº de indicadores de desempeño por subprocesos implementados en el periodo t | G43: Valor indicador= | H43: Valor indicador= | I43: Valor indicador= | J43: Valor indicador= | K43: Valor indicador= | L43: Valor indicador= | M43: Valor indicador= | N43: Valor indicador= | O43: Valor indicador= | P43: Valor indicador= | Q43: Valor indicador= | R43: Valor indicador= | S43: Valor indicador= | T43: Valor indicador= | U43: Valor indicador= | V43: Valor indicador= | W43: Valor indicador= | X43: Valor indicador= | Y43: Valor indicador= | Z43: Valor indicador= | AA43: Valor indicador= | AB43: Valor indicador= | AC43: Valor indicador= | AD43: Valor indicador=
...

Sheet Proyecciones
C1: PLANTILLA SIG COMPROMISOS INSTITUCIONALES | G1: DIVISIÓN PLANIFICACION Y DESARROLLO
G2: DEPARTAMENTO COMPROMISOS INSTITUCIONALES
G3: SUBDEPARTAMENTO GESTION DE INDICADORES INSTITUCIONALES
G5: Fecha:agosto 2025
B6: Elaborado por: Analista de Gestión | C6: Revisado por: Jefa Subdepartamento Gestión de Indicadores Institucionales | G6: Aprobado por: Jefa Departamento Compromisos Institucionales
B7: PROYECCIONES
B8: Convenio de Desempeño Alta Dirección Pública
B9: Jefe Departamento Gestión Beneficios, Sr. Jorge Zúñiga Martínez
B10: Primer Período, tercer año agosto 2025 - julio 2026
A11: NUMERO | B11: INDICADOR | C11: FORMULA | D11: PONDERACIÖN | E11: Meta | F11: Operandos | G11: Operandos Estimados Meta | H11: 45870 | I11: 45901 | J11: Acum. | K11: 45931 | L11: Acum. | M11: 45962 | N11: Acum. | O11: 45992 | P11: Acum. | Q11: 46023 | R11: Acum. | S11: 46054 | T11: Acum. | U11: 46082 | V11: Acum. | W11: 46113 | X11: Acum. | Y11: 46143 | Z11: Acum. | AA11: 46174 | AB11: Acum. | AC11: 46204 | AD11: Cumplimiento Efectivo a la fecha | AE11: % Cumplimiento de Meta
A13: ADP_BENEF_01 | B13: 1. Porcentaje de actividades cumplidos del plan para la aplicación de la encuesta de Satisfacción Neta de usuarios | C13: (Sumatoria de actividades cumplidas del plan para la aplicación de la encuesta de Satisfacción Neta de usuarios / Número total de actividades definidas en el plan para la aplicación de la encuesta de Satisfacción Neta de usuarios) *100 | D13: 0.15 | E13: 1 | F13: Sumatoria de actividades cumplidas del plan para la aplicación de la encuesta de Satisfacción Neta de usuarios | G13: Valor indicador= | H13: Valor indicador= | I13: Valor indicador= | J13: Valor indicador= | K13: Valor indicador= | L13: Valor indicador= | M13: Valor indicador= | N13: Valor indicador= | O13: Valor indicador= | P13: Valor indicador= | Q13: Valor indicador= | R13: Valor indicador= | S13: Valor indicador= | T13: Valor indicador= | U13: Valor indicador= | V13: Valor indicador= | W13: Valor indicador= | X13: Valor indicador= | Y13: Valor indicador= | Z13: Valor indicador= | AA13: Valor indicador= | AB13: Valor indicador= | AC13: Valor indicador= | AD13: Valor indicador=
G14: =IF(G16<>0,ROUND(+G16/G18,4),0%) -> 0 | H14: =IF(H16<>0,ROUND(+H16/H18,4),0%) -> 0 | I14: =IF(I16<>0,ROUND(+I16/I18,4),0%) -> 0 | J14: =IF(J16<>0,ROUND(+J16/J18,4),0%) -> 0 | K14: =IF(K16<>0,ROUND(+K16/K18,4),0%) -> 0 | L14: =IF(L16<>0,ROUND(+L16/L18,4),0%) -> 0 | M14: =IF(M16<>0,ROUND(+M16/M18,4),0%) -> 0 | N14: =IF(N16<>0,ROUND(+N16/N18,4),0%) -> 0 | ... AD14: =IF(AD16<>0,ROUND(+AD16/AD18,4),0%) -> 0
G15: Operando 1= | H15: Operando 1= | I15: Operando 1= | J15: Operando 1= | K15: Operando 1= | L15: Operando 1= | M15: Operando 1= | N15: Operando 1= | O15: Operando 1= | P15: Operando 1= | Q15: Operando 1= | R15: Operando 1= | S15: Operando 1= | T15: Operando 1= | U15: Operando 1= | V15: Operando 1= | W15: Operando 1= | X15: Operando 1= | Y15: Operando 1= | Z15: Operando 1= | AA15: Operando 1= | AB15: Operando 1= | AC15: Operando 1= | AD15: Operando 1=
F16: Número total de actividades definidas en el plan para la aplicación de la encuesta de Satisfacción Neta de usuarios | J16: =+H16+I16 -> 0 | L16: =+J16+K16 -> 0 | N16: =+L16+M16 -> 0 | P16: =+N16+O16 -> 0 | R16: =+P16+Q16 -> 0 | T16: =+R16+S16 -> 0 | V16: =+T16+U16 -> 0 | X16: =+V16+W16 -> 0 | Z16: =+X16+Y16 -> 0 | AB16: =+Z16+AA16 -> 0 | AD16: =+AB16+AC16 -> 0 | AE16: =AD14/E13 -> 0
G17: Operando 2= | H17: Operando 2= | I17: Operando 2= | J17: Operando 2= | K17: Operando 2= | L17: Operando 2= | M17: Operando 2= | N17: Operando 2= | O17: Operando 2= | P17: Operando 2= | Q17: Operando 2= | R17: Operando 2= | S17: Operando 2= | T17: Operando 2= | U17: Operando 2= | V17: Operando 2= | W17: Operando 2= | X17: Operando 2= | Y17: Operando 2= | Z17: Operando 2= | AA17: Operando 2= | AB17: Operando 2= | AC17: Operando 2= | AD17: Operando 2=
J18: =I18 -> 0 | L18: =K18 -> 0 | N18: =M18 -> 0 | P18: =O18 -> 0 | R18: =Q18 -> 0 | T18: =S18 -> 0 | V18: =U18 -> 0 | X18: =W18 -> 0 | Z18: =Y18 -> 0 | AB18: =AA18 -> 0 | AD18: =AC18 -> 0
A19: ADP_BENEF_02 | B19: 2. Porcentaje de proyectos priorizados por el Depto. de Gestión de Beneficios finalizados al año t | C19: (Sumatoria de proyectos priorizados por el Depto. de Gestión de Beneficios finalizados al año t / Número total de proyectos priorizados por el Depto. de Gestión de Beneficios planificados para el periodo) *100 | D19: 0.15 | E19: 0.6667 | F19: Sumatoria de proyectos priorizados por el Depto. de Gestión de Beneficios finalizados al año t | G19: Valor indicador= | H19: Valor indicador= | I19: Valor indicador= | J19: Valor indicador= | K19: Valor indicador= | L19: Valor indicador= | M19: Valor indicador= | N19: Valor indicador= | O19: Valor indicador= | P19: Valor indicador= | Q19: Valor indicador= | R19: Valor indicador= | S19: Valor indicador= | T19: Valor indicador= | U19: Valor indicador= | V19: Valor indicador= | W19: Valor indicador= | X19: Valor indicador= | Y19: Valor indicador= | Z19: Valor indicador= | AA19: Valor indicador= | AB19: Valor indicador= | AC19: Valor indicador= | AD19: Valor indicador=
G20: =IF(G22<>0,ROUND(+G22/G24,4),0%) -> 0 | H20: =IF(H22<>0,ROUND(+H22/H24,4),0%) -> 0 | I20: =IF(I22<>0,ROUND(+I22/I24,4),0%) -> 0 | J20: =IF(J22<>0,ROUND(+J22/J24,4),0%) -> 0 | K20: =IF(K22<>0,ROUND(+K22/K24,4),0%) -> 0 | L20: =IF(L22<>0,ROUND(+L22/L24,4),0%) -> 0 | M20: =IF(M22<>0,ROUND(+M22/M24,4),0%) -> 0 | N20: =IF(N22<>0,ROUND(+N22/N24,4),0%) -> 0 | ... AD20: =IF(AD22<>0,ROUND(+AD22/AD24,4),0%) -> 0
G21: Operando 1= | H21: Operando 1= | I21: Operando 1= | J21: Operando 1= | K21: Operando 1= | L21: Operando 1= | M21: Operando 1= | N21: Operando 1= | O21: Operando 1= | P21: Operando 1= | Q21: Operando 1= | R21: Operando 1= | S21: Operando 1= | T21: Operando 1= | U21: Operando 1= | V21: Operando 1= | W21: Operando 1= | X21: Operando 1= | Y21: Operando 1= | Z21: Operando 1= | AA21: Operando 1= | AB21: Operando 1= | AC21: Operando 1= | AD21: Operando 1=
F22: Número total de proyectos priorizados por el Depto. de Gestión de Beneficios planificados para el periodo | J22: =+H22+I22 -> 0 | L22: =+J22+K22 -> 0 | N22: =+L22+M22 -> 0 | P22: =+N22+O22 -> 0 | R22: =+P22+Q22 -> 0 | T22: =+R22+S22 -> 0 | V22: =+T22+U22 -> 0 | X22: =+V22+W22 -> 0 | Z22: =+X22+Y22 -> 0 | AB22: =+Z22+AA22 -> 0 | AD22: =+AB22+AC22 -> 0 | AE22: =AD20/E19 -> 0
G23: Operando 2= | H23: Operando 2= | I23: Operando 2= | J23: Operando 2= | K23: Operando 2= | L23: Operando 2= | M23: Operando 2= | N23: Operando 2= | O23: Operando 2= | P23: Operando 2= | Q23: Operando 2= | R23: Operando 2= | S23: Operando 2= | T23: Operando 2= | U23: Operando 2= | V23: Operando 2= | W23: Operando 2= | X23: Operando 2= | Y23: Operando 2= | Z23: Operando 2= | AA23: Operando 2= | AB23: Operando 2= | AC23: Operando 2= | AD23: Operando 2=
J24: =I24 -> 0 | L24: =K24 -> 0 | N24: =M24 -> 0 | P24: =O24 -> 0 | R24: =Q24 -> 0 | T24: =S24 -> 0 | V24: =U24 -> 0 | X24: =W24 -> 0 | Z24: =Y24 -> 0 | AB24: =AA24 -> 0 | AD24: =AC24 -> 0
A25: ADP_BENEF_03 | B25: 3. Porcentaje de actividades cumplidas del plan de prevención y control de eventos de riesgo derivados de los procesos claves en el año t | C25: (Sumatoria de actividades cumplidas del plan de prevención y control de eventos de riesgo derivados de los procesos claves en el año t / Sumatoria de actividades definidas en el plan en el año t) *100 | D25: 0.2 | E25: 1 | F25: Sumatoria de actividades cumplidas del plan de prevención y control de eventos de riesgo derivados de los procesos claves en el año t | G25: Valor indicador= | H25: Valor indicador= | I25: Valor indicador= | J25: Valor indicador= | K25: Valor indicador= | L25: Valor indicador= | M25: Valor indicador= | N25: Valor indicador= | O25: Valor indicador= | P25: Valor indicador= | Q25: Valor indicador= | R25: Valor indicador= | S25: Valor indicador= | T25: Valor indicador= | U25: Valor indicador= | V25: Valor indicador= | W25: Valor indicador= | X25: Valor indicador= | Y25: Valor indicador= | Z25: Valor indicador= | AA25: Valor indicador= | AB25: Valor indicador= | AC25: Valor indicador= | AD25: Valor indicador=
G26: =IF(G28<>0,ROUND(+G28/G30,4),0%) -> 1 | H26: =IF(H28<>0,ROUND(+H28/H30,4),0%) -> 0 | I26: =IF(I28<>0,ROUND(+I28/I30,4),0%) -> 0 | J26: =IF(J28<>0,ROUND(+J28/J30,4),0%) -> 0 | K26: =IF(K28<>0,ROUND(+K28/K30,4),0%) -> 0 | L26: =IF(L28<>0,ROUND(+L28/L30,4),0%) -> 0 | M26: =IF(M28<>0,ROUND(+M28/M30,4),0%) -> 0 | N26: =IF(N28<>0,ROUND(+N28/N30,4),0%) -> 0 | ... AD26: =IF(AD28<>0,ROUND(+AD28/AD30,4),0%) -> 0
G27: Operando 1= | H27: Operando 1= | I27: Operando 1= | J27: Operando 1= | K27: Operando 1= | L27: Operando 1= | M27: Operando 1= | N27: Operando 1= | O27: Operando 1= | P27: Operando 1= | Q27: Operando 1= | R27: Operando 1= | S27: Operando 1= | T27: Operando 1= | U27: Operando 1= | V27: Operando 1= | W27: Operando 1= | X27: Operando 1= | Y27: Operando 1= | Z27: Operando 1= | AA27: Operando 1= | AB27: Operando 1= | AC27: Operando 1= | AD27: Operando 1=
F28: Sumatoria de actividades definidas en el plan en el año t | G28: 5 | J28: =+H28+I28 -> 0 | L28: =+J28+K28 -> 0 | N28: =+L28+M28 -> 0 | P28: =+N28+O28 -> 0 | R28: =+P28+Q28 -> 0 | T28: =+R28+S28 -> 0 | V28: =+T28+U28 -> 0 | X28: =+V28+W28 -> 0 | Z28: =+X28+Y28 -> 0 | AB28: =+Z28+AA28 -> 0 | AD28: =+AB28+AC28 -> 0 | AE28: =AD26/E25 -> 0
G29: Operando 2= | H29: Operando 2= | I29: Operando 2= | J29: Operando 2= | K29: Operando 2= | L29: Operando 2= | M29: Operando 2= | N29: Operando 2= | O29: Operando 2= | P29: Operando 2= | Q29: Operando 2= | R29: Operando 2= | S29: Operando 2= | T29: Operando 2= | U29: Operando 2= | V29: Operando 2= | W29: Operando 2= | X29: Operando 2= | Y29: Operando 2= | Z29: Operando 2= | AA29: Operando 2= | AB29: Operando 2= | AC29: Operando 2= | AD29: Operando 2=
G30: 5 | J30: =I30 -> 0 | L30: =K30 -> 0 | N30: =M30 -> 0 | P30: =O30 -> 0 | R30: =Q30 -> 0 | T30: =S30 -> 0 | V30: =U30 -> 0 | X30: =W30 -> 0 | Z30: =Y30 -> 0 | AB30: =AA30 -> 0 | AD30: =AC30 -> 0
A31: ADP_BENEF_04 | B31: 4. Porcentaje de actividades cumplidas del plan de trabajo anual para mejorar la Satisfacción Laboral el año t | C31: (Sumatoria de actividades cumplidas del plan de trabajo anual para mejorar la Satisfacción Laboral en el año t / Nº total de actividades planificadas del plan de trabajo anual para mejorar la Satisfacción Laboral en el año t) *100 | D31: 0.15 | E31: 1 | F31: Sumatoria de actividades cumplidas del plan de trabajo anual para mejorar la Satisfacción Laboral en el año t | G31: Valor indicador= | H31: Valor indicador= | I31: Valor indicador= | J31: Valor indicador= | K31: Valor indicador= | L31: Valor indicador= | M31: Valor indicador= | N31: Valor indicador= | O31: Valor indicador= | P31: Valor indicador= | Q31: Valor indicador= | R31: Valor indicador= | S31: Valor indicador= | T31: Valor indicador= | U31: Valor indicador= | V31: Valor indicador= | W31: Valor indicador= | X31: Valor indicador= | Y31: Valor indicador= | Z31: Valor indicador= | AA31: Valor indicador= | AB31: Valor indicador= | AC31: Valor indicador= | AD31: Valor indicador=
G32: =IF(G34<>0,ROUND(+G34/G36,4),0%) -> 0 | H32: =IF(H34<>0,ROUND(+H34/H36,4),0%) -> 0 | I32: =IF(I34<>0,ROUND(+I34/I36,4),0%) -> 0 | J32: =IF(J34<>0,ROUND(+J34/J36,4),0%) -> 0 | K32: =IF(K34<>0,ROUND(+K34/K36,4),0%) -> 0 | L32: =IF(L34<>0,ROUND(+L34/L36,4),0%) -> 0 | M32: =IF(M34<>0,ROUND(+M34/M36,4),0%) -> 0 | N32: =IF(N34<>0,ROUND(+N34/N36,4),0%) -> 0 | ... AD32: =IF(AD34<>0,ROUND(+AD34/AD36,4),0%) -> 0
G33: Operando 1= | H33: Operando 1= | J33: Operando 1= | K33: Operando 1= | L33: Operando 1= | M33: Operando 1= | N33: Operando 1= | O33: Operando 1= | P33: Operando 1= | Q33: Operando 1= | R33: Operando 1= | S33: Operando 1= | T33: Operando 1= | U33: Operando 1= | V33: Operando 1= | W33: Operando 1= | X33: Operando 1= | Y33: Operando 1= | Z33: Operando 1= | AA33: Operando 1= | AB33: Operando 1= | AC33: Operando 1= | AD33: Operando 1=
F34: Nº total de actividades planificadas del plan de trabajo anual para mejorar la Satisfacción Laboral en el año t | J34: =+H34+I34 -> 0 | L34: =+J34+K34 -> 0 | N34: =+L34+M34 -> 0 | P34: =+N34+O34 -> 0 | R34: =+P34+Q34 -> 0 | T34: =+R34+S34 -> 0 | V34: =+T34+U34 -> 0 | X34: =+V34+W34 -> 0 | Z34: =+X34+Y34 -> 0 | AB34: =+Z34+AA34 -> 0 | AD34: =+AB34+AC34 -> 0 | AE34: =AD32/E31 -> 0
G35: Operando 2= | H35: Operando 2= | I35: Operando 2= | J35: Operando 2= | K35: Operando 2= | L35: Operando 2= | M35: Operando 2= | N35: Operando 2= | O35: Operando 2= | P35: Operando 2= | Q35: Operando 2= | R35: Operando 2= | S35: Operando 2= | T35: Operando 2= | U35: Operando 2= | V35: Operando 2= | W35: Operando 2= | X35: Operando 2= | Y35: Operando 2= | Z35: Operando 2= | AA35: Operando 2= | AB35: Operando 2= | AC35: Operando 2= | AD35: Operando 2=
J36: =I36 -> 0 | L36: =K36 -> 0 | N36: =M36 -> 0 | P36: =O36 -> 0 | R36: =Q36 -> 0 | T36: =S36 -> 0 | V36: =U36 -> 0 | X36: =W36 -> 0 | Z36: =Y36 -> 0 | AB36: =AA36 -> 0 | AD36: =AC36 -> 0
A37: ADP_BENEF_05 | B37: 5. Porcentaje de hitos cumplidos del Plan de Gestión del Conocimiento de Cargos Críticos | C37: (Sumatoria del cumplimiento de hitos del Plan de Gestión del Conocimiento comprometidos en el período / Nº total de hitos planificados del plan de Gestión del Conocimiento en el periodo) *100 | D37: 0.15 | E37: 1 | F37: Sumatoria del cumplimiento de hitos del Plan de Gestión del Conocimiento comprometidos en el período | G37: Valor indicador= | H37: Valor indicador= | I37: Valor indicador= | J37: Valor indicador= | K37: Valor indicador= | L37: Valor indicador= | M37: Valor indicador= | N37: Valor indicador= | O37: Valor indicador= | P37: Valor indicador= | Q37: Valor indicador= | R37: Valor indicador= | S37: Valor indicador= | T37: Valor indicador= | U37: Valor indicador= | V37: Valor indicador= | W37: Valor indicador= | X37: Valor indicador= | Y37: Valor indicador= | Z37: Valor indicador= | AA37: Valor indicador= | AB37: Valor indicador= | AC37: Valor indicador= | AD37: Valor indicador=
G38: =IF(G40<>0,ROUND(+G40/G42,4),0%) -> 0 | H38: =IF(H40<>0,ROUND(+H40/H42,4),0%) -> 0 | I38: =IF(I40<>0,ROUND(+I40/I42,4),0%) -> 0 | J38: =IF(J40<>0,ROUND(+J40/J42,4),0%) -> 0 | K38: =IF(K40<>0,ROUND(+K40/K42,4),0%) -> 0 | L38: =IF(L40<>0,ROUND(+L40/L42,4),0%) -> 0 | M38: =IF(M40<>0,ROUND(+M40/M42,4),0%) -> 0 | N38: =IF(N40<>0,ROUND(+N40/N42,4),0%) -> 0 | ... AD38: =IF(AD40<>0,ROUND(+AD40/AD42,4),0%) -> 0
G39: Operando 1= | H39: Operando 1= | J39: Operando 1= | K39: Operando 1= | L39: Operando 1= | M39: Operando 1= | N39: Operando 1= | O39: Operando 1= | P39: Operando 1= | Q39: Operando 1= | R39: Operando 1= | S39: Operando 1= | T39: Operando 1= | U39: Operando 1= | V39: Operando 1= | W39: Operando 1= | X39: Operando 1= | Y39: Operando 1= | Z39: Operando 1= | AA39: Operando 1= | AB39: Operando 1= | AC39: Operando 1= | AD39: Operando 1=
F40: Nº total de hitos planificados del plan de Gestión del Conocimiento en el periodo | J40: =+H40+I40 -> 0 | L40: =+J40+K40 -> 0 | N40: =+L40+M40 -> 0 | P40: =+N40+O40 -> 0 | R40: =+P40+Q40 -> 0 | T40: =+R40+S40 -> 0 | V40: =+T40+U40 -> 0 | X40: =+V40+W40 -> 0 | Z40: =+X40+Y40 -> 0 | AB40: =+Z40+AA40 -> 0 | AD40: =+AB40+AC40 -> 0 | AE40: =AD38/E37 -> 0
G41: Operando 2= | H41: Operando 2= | I41: Operando 2= | J41: Operando 2= | K41: Operando 2= | L41: Operando 2= | M41: Operando 2= | N41: Operando 2= | O41: Operando 2= | P41: Operando 2= | Q41: Operando 2= | R41: Operando 2= | S41: Operando 2= | T41: Operando 2= | U41: Operando 2= | V41: Operando 2= | W41: Operando 2= | X41: Operando 2= | Y41: Operando 2= | Z41: Operando 2= | AA41: Operando 2= | AB41: Operando 2= | AC41: Operando 2= | AD41: Operando 2=
J42: =I42 -> 0 | L42: =K42 -> 0 | N42: =M42 -> 0 | P42: =O42 -> 0 | R42: =Q42 -> 0 | T42: =S42 -> 0 | V42: =U42 -> 0 | X42: =W42 -> 0 | Z42: =Y42 -> 0 | AB42: =AA42 -> 0 | AD42: =AC42 -> 0
...

Sheet Consolidado
A1: CONVENIO DE DESEMPEÑO ALTA DIRECCIÓN PÚBLICA
A3: Jefe Departamento Gestión Beneficios, Sr. Jorge Zúñiga Martínez (ago 2025 - julio 2026)
A5: Indicador | B5: Fórmula de Cálculo | C5: Pond. | D5: Meta | E5: Valores según Fórmula de Cálculo | G5: % Cumpli- miento | H5: Total Pond. | I5: Proyección
E7: Operandos | F7: Efectivo a enero 2026 | I7: Resultado a enero 2026 | J7: % Cumpli- miento | K7: Pond.
A8: 1. Porcentaje de actividades cumplidos del plan para la aplicación de la encuesta de Satisfacción Neta de usuarios | B8: (Sumatoria de actividades cumplidas del plan para la aplicación de la encuesta de Satisfacción Neta de usuarios / Número total de actividades definidas en el plan para la aplicación de la encuesta de Satisfacción Neta de usuarios) *100 | C8: 0.15 | D8: 1 | E8: =+'Plantilla SIG'!AD16 -> 4 | F8: =+'Plantilla SIG'!AD14 -> 1 | G8: =F8/D8 -> 1 | H8: =IF(G8>100%,C8,G8*C8) -> 0.15 | I8: 1 | J8: =+I8/D8 -> 1 | K8: 0.15
E9: =+'Plantilla SIG'!AD18 -> 4 | H9: =IF(G9>100%,D9,G9*D9) -> 0 | K9: =IF(J9>100%,G9,J9*G9) -> 0
A10: 2. Porcentaje de proyectos priorizados por el Depto. de Gestión de Beneficios finalizados al año t | B10: (Sumatoria de proyectos priorizados por el Depto. de Gestión de Beneficios finalizados al año t / Número total de proyectos priorizados por el Depto. de Gestión de Beneficios planificados para el periodo) *100 | C10: 0.15 | D10: 1 | E10: =+'Plantilla SIG'!AD22 -> 0 | F10: =E10/E11 -> 0 | G10: =F10/D10 -> 0 | H10: =IF(G10>100%,C10,G10*C10) -> 0 | I10: =+Proyecciones!J20 -> 0 | J10: =+I10/D10 -> 0 | K10: =IF(J10>100%,C10,J10*C10) -> 0
E11: =+'Plantilla SIG'!AD24 -> 1 | H11: =IF(G11>100%,D11,G11*D11) -> 0 | K11: =IF(J11>100%,G11,J11*G11) -> 0
A12: 3. Porcentaje de actividades cumplidas del plan de prevención y control de eventos de riesgo derivados de los procesos claves en el año t | B12: (Sumatoria de actividades cumplidas del plan de prevención y control de eventos de riesgo derivados de los procesos claves en el año t / Sumatoria de actividades definidas en el plan en el año t) *100 | C12: 0.2 | D12: 1 | E12: =+'Plantilla SIG'!AD28 -> 1 | F12: =+'Plantilla SIG'!AD26 -> 0.2 | G12: =F12/D12 -> 0.2 | H12: =IF(G12>100%,C12,G12*C12) -> 0.04 | I12: 0.2 | J12: =+I12/D12 -> 0.2 | K12: =IF(J12>100%,C12,J12*C12) -> 0.04
E13: =+'Plantilla SIG'!AD30 -> 5 | H13: =IF(G13>100%,D13,G13*D13) -> 0 | K13: =IF(J13>100%,G13,J13*G13) -> 0
A14: 4. Porcentaje de actividades cumplidas del plan de trabajo anual para mejorar la Satisfacción Laboral el año t | B14: (Sumatoria de actividades cumplidas del plan de trabajo anual para mejorar la Satisfacción Laboral en el año t / Nº total de actividades planificadas del plan de trabajo anual para mejorar la Satisfacción Laboral en el año t) *100 | C14: 0.15 | D14: 1 | E14: ='Plantilla SIG'!AD34 -> 2 | F14: ='Plantilla SIG'!AD32 -> 0.5 | G14: =F14/D14 -> 0.5 | H14: =IF(G14>100%,C14,G14*C14) -> 0.075 | I14: 0.5 | J14: =+I14/D14 -> 0.5 | K14: =IF(J14>100%,C14,J14*C14) -> 0.075
E15: ='Plantilla SIG'!AD36 -> 4 | H15: =IF(G15>100%,D15,G15*D15) -> 0 | K15: =IF(J15>100%,G15,J15*G15) -> 0
A16: 5. Porcentaje de hitos cumplidos del Plan de Gestión del Conocimiento de Cargos Críticos | B16: (Sumatoria del cumplimiento de hitos del Plan de Gestión del Conocimiento comprometidos en el período / Nº total de hitos planificados del plan de Gestión del Conocimiento en el periodo) *100 | C16: 0.15 | D16: 1 | E16: ='Plantilla SIG'!AD40 -> 1 | F16: ='Plantilla SIG'!AD38 -> 0.5 | G16: =F16/D16 -> 0.5 | H16: =IF(G16>100%,C16,G16*C16) -> 0.075 | I16: 0.5 | J16: =+I16/D16 -> 0.5 | K16: =IF(J16>100%,C16,J16*C16) -> 0.075
E17: ='Plantilla SIG'!AD42 -> 2 | H17: =IF(G17>100%,D17,G17*D17) -> 0 | K17: =IF(J17>100%,G17,J17*G17) -> 0
A18: 6. Porcentaje de indicadores de desempeño por subproceso o proceso implementados en el periodo t | B18: (Nº de indicadores de desempeño por subprocesos implementados en el periodo t / Nº total de indicadores planificados para implementar en el periodo) *100 | C18: 0.1 | D18: 1 | E18: ='Plantilla SIG'!AD46 -> 2 | F18: ='Plantilla SIG'!AD44 -> 0.6667 | G18: =F18/D18 -> 0.6667 | H18: =IF(G18>100%,C18,G18*C18) -> 0.06667 | I18: 0.6667 | J18: =+I18/D18 -> 0.6667 | K18: =IF(J18>100%,C18,J18*C18) -> 0.06667 | M18: Falta planilla SIG de Indicador y Ficha técnica corregida
E19: ='Plantilla SIG'!AD48 -> 3 | H19: =IF(G19>100%,D19,G19*D19) -> 0 | K19: =IF(J19>100%,G19,J19*G19) -> 0
A20: 7. Porcentaje de actividades de Sensibilización en aspectos de la NCh3262 realizadas en el Departamento. | B20: (N° de actividades de Sensibilización implementadas en el periodo / N° de actividades de Sensibilización planificadas para el periodo) *100. | C20: 0.1 | D20: 1 | E20: ='Plantilla SIG'!AD52 -> 1 | F20: ='Plantilla SIG'!AD50 -> 0.5 | G20: =F20/D20 -> 0.5 | H20: =IF(G20>100%,C20,G20*C20) -> 0.05 | I20: 0.5 | J20: =+I20/D20 -> 0.5 | K20: =IF(J20>100%,C20,J20*C20) -> 0.05
E21: ='Plantilla SIG'!AD54 -> 2 | H21: =IF(G21>100%,D21,G21*D21) -> 0 | K21: =IF(J21>100%,G21,J21*G21) -> 0
C22: =+SUM(C8:C21) -> 1 | E22: % de cumplimiernto informado | H22: =H8+H10+H12+H14+H16+H20+H18 -> 0.45667 | K22: =+SUM(K8:K21) -> 0.45667
E23: % de cumplimiento por informar | H23: =+H24-H22 -> 0.54333
E24: % de cumplimiento esperado | H24: 1
